Workbook

Sheet CoverPage
A1: FINANCIAL MODELING USING EXCEL
A3: Required Periodic Deposit Modeling Using Excel (PMT Function)
A5: Time Value of Money and Goal-Based Savings Analysis
A7: Workbook Purpose
A9: This workbook is specifically designed to determine the required periodic deposit (investment or savings amount) needed to accumulate a predefined future value within a given time horizon, interest rate, and compounding structure. The workbook focuses exclusively on deposit determination, not loan payments or amortization. By working through this model, learners understand how financial goals—such as education funds, retirement corpus, or planned expenditures—can be translated into systematic savings requirements. The workbook uses Excel to operationalize time value of money concepts, enabling learners to assess feasibility, compare scenarios, and interpret required savings amounts in realistic financial planning contexts.
A15: Key Concepts Covered | I15: Excel Functions Used
A16: Time value of money in systematic savings decisions Goal-based financial planning and target accumulation Relationship between required deposit, interest rate, and time horizon Role of compounding frequency in savings accumulation Cash flow direction from an investor’s perspective Sensitivity of required deposits to changes in return assumptions Practical interpretation of savings requirements for financial planning | I16: PMT – Computes the required periodic deposit to achieve a target value FV – Represents the target future corpus or financial goal RATE – Defines the assumed return on savings or investments NPER – Aligns investment horizon with deposit frequency IF – Handles logical conditions and scenario-specific structure ABS – Enforces disciplined cash-flow sign conventions Strong emphasis is placed on correct sign handling, frequency alignment, and clear interpretation of deposit outputs.
E18: Srikanth Potharla is an accounting and finance educator with over fifteen years of teaching and industry-oriented experience. Currently serving as Assistant Professor at ICFAI Business School, Hyderabad, he specializes in financial modeling using Excel, valuation, and data analytics. His work bridges theory and practice through structured models, real-world applications, and hands-on learning resources designed for MBA, professional, and global learners.

Sheet Index
B1: Index
A2: 1 | B2: Income Statement
A3: 2 | B3: Balance Sheet
A4: 3 | B4: Comparative Income Statement
A5: 4 | B5: Comparative Balance Sheet
A6: 5 | B6: Common Size Income Statement
A7: 6 | B7: Common Size Balance Sheet

Sheet IS
A1: Income Statement of Tata Motors from FY2020 TO FY2024
A2: Particulars | B2: FY2024 | C2: FY2023 | D2: FY2022 | E2: FY2021 | F2: FY2020
A3: I. Revenue from operations
A4: (a) Revenue | B4: 72745.92 | C4: 65298.84 | D4: 46880.97 | E4: 46559.39 | F4: 43485.76
A5: (b) Other operating revenue | B5: 557.16 | C5: 458.49 | D5: 382.71 | E5: 472.08 | F5: 442.41
A6: Total revenue from operations (I) | B6: 73303.08 | C6: 65757.33 | D6: 47263.68 | E6: 47031.47 | F6: 43928.17
A7: II. Other Income | B7: 1149.88 | C7: 820.94 | D7: 659.91 | E7: 842.96 | F7: 1383.05
A8: III. Total Income (I+II) | B8: 74452.96 | C8: 66578.27 | D8: 47923.59 | E8: 47874.43 | F8: 45311.22
A9: IV. Expenses:
A10: (a) Cost of materials consumed | B10: 46757.28 | C10: 42226.81 | D10: 31693.11 | E10: 28493.12 | F10: 26171.85
A11: (b) Purchases of products for sale | B11: 6707.03 | C11: 6561.32 | D11: 5030 | E11: 7518.05 | F11: 5679.98
A12: (c) Changes in Stock | B12: 1736.35 | C12: 484.69 | D12: -403.87 | E12: -108.48 | F12: 722.68
A13: (d) Employee benefits expense | B13: 4308.15 | C13: 4021.63 | D13: 3601.51 | E13: 3987.72 | F13: 4384.31
A14: (e) Finance costs | B14: 1705.74 | C14: 2047.51 | D14: 2121.73 | E14: 2288.61 | F14: 1973
A15: (f) Foreign exchange loss (net) | B15: 200.72 | C15: 279.76 | D15: 136.81 | E15: 29.02 | F15: 239
A16: (g) Depreciation and amortisation expense | B16: 2016.84 | C16: 1766.86 | D16: 1760.57 | E16: 3325.8 | F16: 3375.29
A17: (h) Product development/Engineering expenses | B17: 1104.79 | C17: 899.06 | D17: 593.9 | E17: 907.44 | F17: 830.24
A18: (i) Other expenses | B18: 7610.15 | C18: 7819.74 | D18: 6018.71 | E18: 5612.48 | F18: 7720.75
A19: (j) Amount transferred to capital and other accounts | B19: -1129.73 | C19: -1066.73 | D19: -905.42 | E19: -817.53 | F19: -1169.46
A20: Total Expenses (IV) | B20: 69317.32 | C20: 65040.65 | D20: 49647.05 | E20: 51239.38 | F20: 49927.64
A21: V. Profit/(Loss) before exceptional items and tax (III-IV) | B21: 5135.64 | C21: 1537.62 | D21: -1723.46 | E21: -3364.95 | F21: -4616.42
... A27: XI. Total comprehensive income/(loss) for the year | B27: 8338.64 | C27: 2451.64 | D27: -1267.18 | E27: -1952.45 | F27: -7668.35

Sheet BS
A1: Balance Sheet of Tata Motors from FY2020 TO FY2024
A2: Particulars | B2: FY2024 | C2: FY2023 | D2: FY2022 | E2: FY2021 | F2: FY2020
A3: I. ASSETS
A4: (1) NON-CURRENT ASSETS | B4: 36133.09 | C4: 33060.22 | D4: 30958.82 | E4: 30283.65 | F4: 47242.06
A5: Property, plant and equipment (PPE) | B5: 12056.24 | C5: 12176.6 | D5: 11811.02 | E5: 17143.04 | F5: 18870.67
A6: Capital work-in-progress (CWIP) | B6: 575.65 | C6: 575.65 | D6: 585.21 | E6: 1324.21 | F6: 1755.51
A7: Right of use assets (ROU) | B7: 338.25 | C7: 344.2 | D7: 332.45 | E7: 979.48 | F7: 669.58
A8: Goodwill | B8: 99.09 | C8: 99.09 | D8: 99.09 | E8: 99.09 | F8: 99.09
A9: Other intangible assets | B9: 1768.49 | C9: 1914.76 | D9: 2009.87 | E9: 6156.56 | F9: 5568.64
A10: Intangible assets under development | B10: 509.3 | C10: 509.3 | D10: 882.03 | E10: 1604.23 | F10: 2739.29
A11: Investments in subsidiaries, JVs & associates | B11: 25819.34 | C11: 27976.8 | D11: 24723.34 | E11: 14287.8 | F11: 15182.29
A12: Financial assets (Investments, Loans, Others) | B12: -1283.47 | C12: -1402.16 | D12: -1507.57 | E12: 1691.01 | F12: 2204.53
A13: Non-current tax assets (Net) | B13: 1751.48 | C13: 1909.8 | D13: 1847.16 | E13: 741.02 | F13: 727.97
A14: Other non-current assets | B14: -1301.98 | C14: -1439.42 | D14: -2059.45 | E14: 1056.77 | F14: 1208.08
A15: (2) CURRENT ASSETS | B15: 36258.71 | C15: 26868.97 | D15: 26792.13 | E15: 25309.78 | F15: 7861.82
... A20: TOTAL ASSETS (1) + (2) | B20: 72391.8 | C20: 59929.19 | D20: 57750.95 | E20: 55593.43 | F20: 55103.88
A22: II. EQUITY AND LIABILITIES
A23: (1) EQUITY | B23: 34068.79 | C23: 28683.65 | D23: 27786.17 | E23: 27173.34 | F23: 24545.91
A24: Equity share capital | B24: 766.49 | C24: 766.02 | D24: 765.88 | E24: 765.81 | F24: 719.54
A25: Other equity | B25: 33302.3 | C25: 27917.63 | D25: 27020.29 | E25: 26407.53 | F25: 23826.37
A26: (2) NON-CURRENT LIABILITIES | B26: 14449.18 | C26: 10501.71 | D26: 9436.56 | E26: 10544.75 | F26: 13293.48
A27: Financial liabilities (Borrowings & Lease) | B27: 11632.4 | C27: 7654.51 | D27: 6560.85 | E27: 7728.84 | F27: 10234.34
A28: Provisions | B28: 2752.48 | C28: 2787.05 | D28: 2828.53 | E28: 2776.99 | F28: 3030.14
A29: Deferred tax liabilities (Net) | B29: -7.8 | C29: 1.83 | D29: 1.84 | E29: -373.19 | F29: 7.92
A30: Other non-current liabilities | B30: 72.1 | C30: 58.32 | D30: 45.34 | E30: 412 | F30: 21.08
A31: (3) CURRENT LIABILITIES | B31: 23873.83 | C31: 20743.83 | D31: 20528.22 | E31: 17875.34 | F31: 17264.49
A32: Financial liabilities (Borrowings, Trade Payables, Others) | B32: 22234.33 | C32: 18973.91 | D32: 18913.34 | E32: 16339.06 | F32: 15360.7
A33: Provisions | B33: 1023.7 | C33: 1087.49 | D33: 913.04 | E33: 910.16 | F33: 1043.54
A34: Current tax liabilities (Net) | B34: 148.16 | C34: 212.72 | D34: 19.82 | E34: 87.05 | F34: 295.34
... A36: TOTAL EQUITY AND LIABILITIES (1) + (2) + (3) | B36: 72391.8 | C36: 59929.19 | D36: 57750.95 | E36: 55593.43 | F36: 55103.88

Sheet IS_XLOOPUP
A1: =IS!A1
A2: =IS!A2 | B2: =IS!B2 | C2: =IS!C2 | D2: =IS!D2 | E2: =IS!E2 | F2: =IS!F2
A3: =IS!A3
A4: =IS!A4 | B4: =_xlfn.XLOOKUP($A4,IS!$A$1:$A$27,IS!B$1:B$27," ",0,1) | C4: =_xlfn.XLOOKUP($A4,IS!$A$1:$A$27,IS!C$1:C$27," ",0,1) | D4: =_xlfn.XLOOKUP($A4,IS!$A$1:$A$27,IS!D$1:D$27," ",0,1) | E4: =_xlfn.XLOOKUP($A4,IS!$A$1:$A$27,IS!E$1:E$27," ",0,1) | F4: =_xlfn.XLOOKUP($A4,IS!$A$1:$A$27,IS!F$1:F$27," ",0,1)
A5: =IS!A5 | B5: =_xlfn.XLOOKUP($A5,IS!$A$1:$A$27,IS!B$1:B$27," ",0,1) | C5: =_xlfn.XLOOKUP($A5,IS!$A$1:$A$27,IS!C$1:C$27," ",0,1) | D5: =_xlfn.XLOOKUP($A5,IS!$A$1:$A$27,IS!D$1:D$27," ",0,1) | E5: =_xlfn.XLOOKUP($A5,IS!$A$1:$A$27,IS!E$1:E$27," ",0,1) | F5: =_xlfn.XLOOKUP($A5,IS!$A$1:$A$27,IS!F$1:F$27," ",0,1)
A6: =IS!A6 | B6: =_xlfn.XLOOKUP($A6,IS!$A$1:$A$27,IS!B$1:B$27," ",0,1) | C6: =_xlfn.XLOOKUP($A6,IS!$A$1:$A$27,IS!C$1:C$27," ",0,1) | D6: =_xlfn.XLOOKUP($A6,IS!$A$1:$A$27,IS!D$1:D$27," ",0,1) | E6: =_xlfn.XLOOKUP($A6,IS!$A$1:$A$27,IS!E$1:E$27," ",0,1) | F6: =_xlfn.XLOOKUP($A6,IS!$A$1:$A$27,IS!F$1:F$27," ",0,1)
A7: =IS!A7 | B7: =_xlfn.XLOOKUP($A7,IS!$A$1:$A$27,IS!B$1:B$27," ",0,1) | C7: =_xlfn.XLOOKUP($A7,IS!$A$1:$A$27,IS!C$1:C$27," ",0,1) | D7: =_xlfn.XLOOKUP($A7,IS!$A$1:$A$27,IS!D$1:D$27," ",0,1) | E7: =_xlfn.XLOOKUP($A7,IS!$A$1:$A$27,IS!E$1:E$27," ",0,1) | F7: =_xlfn.XLOOKUP($A7,IS!$A$1:$A$27,IS!F$1:F$27," ",0,1)
A8: =IS!A8 | B8: =_xlfn.XLOOKUP($A8,IS!$A$1:$A$27,IS!B$1:B$27," ",0,1) | C8: =_xlfn.XLOOKUP($A8,IS!$A$1:$A$27,IS!C$1:C$27," ",0,1) | D8: =_xlfn.XLOOKUP($A8,IS!$A$1:$A$27,IS!D$1:D$27," ",0,1) | E8: =_xlfn.XLOOKUP($A8,IS!$A$1:$A$27,IS!E$1:E$27," ",0,1) | F8: =_xlfn.XLOOKUP($A8,IS!$A$1:$A$27,IS!F$1:F$27," ",0,1)
A9: =IS!A9 | B9: =_xlfn.XLOOKUP($A9,IS!$A$1:$A$27,IS!B$1:B$27," ",0,1) | C9: =_xlfn.XLOOKUP($A9,IS!$A$1:$A$27,IS!C$1:C$27," ",0,1) | D9: =_xlfn.XLOOKUP($A9,IS!$A$1:$A$27,IS!D$1:D$27," ",0,1) | E9: =_xlfn.XLOOKUP($A9,IS!$A$1:$A$27,IS!E$1:E$27," ",0,1) | F9: =_xlfn.XLOOKUP($A9,IS!$A$1:$A$27,IS!F$1:F$27," ",0,1)
A10: =IS!A10 | B10: =_xlfn.XLOOKUP($A10,IS!$A$1:$A$27,IS!B$1:B$27," ",0,1) | C10: =_xlfn.XLOOKUP($A10,IS!$A$1:$A$27,IS!C$1:C$27," ",0,1) | D10: =_xlfn.XLOOKUP($A10,IS!$A$1:$A$27,IS!D$1:D$27," ",0,1) | E10: =_xlfn.XLOOKUP($A10,IS!$A$1:$A$27,IS!E$1:E$27," ",0,1) | F10: =_xlfn.XLOOKUP($A10,IS!$A$1:$A$27,IS!F$1:F$27," ",0,1)
A11: =IS!A11 | B11: =_xlfn.XLOOKUP($A11,IS!$A$1:$A$27,IS!B$1:B$27," ",0,1) | C11: =_xlfn.XLOOKUP($A11,IS!$A$1:$A$27,IS!C$1:C$27," ",0,1) | D11: =_xlfn.XLOOKUP($A11,IS!$A$1:$A$27,IS!D$1:D$27," ",0,1) | E11: =_xlfn.XLOOKUP($A11,IS!$A$1:$A$27,IS!E$1:E$27," ",0,1) | F11: =_xlfn.XLOOKUP($A11,IS!$A$1:$A$27,IS!F$1:F$27," ",0,1)
A12: =IS!A12 | B12: =_xlfn.XLOOKUP($A12,IS!$A$1:$A$27,IS!B$1:B$27," ",0,1) | C12: =_xlfn.XLOOKUP($A12,IS!$A$1:$A$27,IS!C$1:C$27," ",0,1) | D12: =_xlfn.XLOOKUP($A12,IS!$A$1:$A$27,IS!D$1:D$27," ",0,1) | E12: =_xlfn.XLOOKUP($A12,IS!$A$1:$A$27,IS!E$1:E$27," ",0,1) | F12: =_xlfn.XLOOKUP($A12,IS!$A$1:$A$27,IS!F$1:F$27," ",0,1)
A13: =IS!A13 | B13: =_xlfn.XLOOKUP($A13,IS!$A$1:$A$27,IS!B$1:B$27," ",0,1) | C13: =_xlfn.XLOOKUP($A13,IS!$A$1:$A$27,IS!C$1:C$27," ",0,1) | D13: =_xlfn.XLOOKUP($A13,IS!$A$1:$A$27,IS!D$1:D$27," ",0,1) | E13: =_xlfn.XLOOKUP($A13,IS!$A$1:$A$27,IS!E$1:E$27," ",0,1) | F13: =_xlfn.XLOOKUP($A13,IS!$A$1:$A$27,IS!F$1:F$27," ",0,1)
A14: =IS!A14 | B14: =_xlfn.XLOOKUP($A14,IS!$A$1:$A$27,IS!B$1:B$27," ",0,1) | C14: =_xlfn.XLOOKUP($A14,IS!$A$1:$A$27,IS!C$1:C$27," ",0,1) | D14: =_xlfn.XLOOKUP($A14,IS!$A$1:$A$27,IS!D$1:D$27," ",0,1) | E14: =_xlfn.XLOOKUP($A14,IS!$A$1:$A$27,IS!E$1:E$27," ",0,1) | F14: =_xlfn.XLOOKUP($A14,IS!$A$1:$A$27,IS!F$1:F$27," ",0,1)
A15: =IS!A15 | B15: =_xlfn.XLOOKUP($A15,IS!$A$1:$A$27,IS!B$1:B$27," ",0,1) | C15: =_xlfn.XLOOKUP($A15,IS!$A$1:$A$27,IS!C$1:C$27," ",0,1) | D15: =_xlfn.XLOOKUP($A15,IS!$A$1:$A$27,IS!D$1:D$27," ",0,1) | E15: =_xlfn.XLOOKUP($A15,IS!$A$1:$A$27,IS!E$1:E$27," ",0,1) | F15: =_xlfn.XLOOKUP($A15,IS!$A$1:$A$27,IS!F$1:F$27," ",0,1)
... A27: =IS!A27 | B27: =_xlfn.XLOOKUP($A27,IS!$A$1:$A$27,IS!B$1:B$27," ",0,1) | C27: =_xlfn.XLOOKUP($A27,IS!$A$1:$A$27,IS!C$1:C$27," ",0,1) | D27: =_xlfn.XLOOKUP($A27,IS!$A$1:$A$27,IS!D$1:D$27," ",0,1) | E27: =_xlfn.XLOOKUP($A27,IS!$A$1:$A$27,IS!E$1:E$27," ",0,1) | F27: =_xlfn.XLOOKUP($A27,IS!$A$1:$A$27,IS!F$1:F$27," ",0,1)

Sheet IS_VLOOKUP
A1: =IS!A1
A2: 1 | B2: 2 | C2: 3 | D2: 4 | E2: 5 | F2: 6
A3: =IS!A2 | B3: =IS!B2 | C3: =IS!C2 | D3: =IS!D2 | E3: =IS!E2 | F3: =IS!F2
A4: =IS!A3
A5: =IS!A4 | B5: =IFERROR(VLOOKUP($A5,IS!$A$1:$F$27,B$2,FALSE),"") | C5: =IFERROR(VLOOKUP($A5,IS!$A$1:$F$27,C$2,FALSE),"") | D5: =IFERROR(VLOOKUP($A5,IS!$A$1:$F$27,D$2,FALSE),"") | E5: =IFERROR(VLOOKUP($A5,IS!$A$1:$F$27,E$2,FALSE),"") | F5: =IFERROR(VLOOKUP($A5,IS!$A$1:$F$27,F$2,FALSE),"")
A6: =IS!A5 | B6: =IFERROR(VLOOKUP($A6,IS!$A$1:$F$27,B$2,FALSE),"") | C6: =IFERROR(VLOOKUP($A6,IS!$A$1:$F$27,C$2,FALSE),"") | D6: =IFERROR(VLOOKUP($A6,IS!$A$1:$F$27,D$2,FALSE),"") | E6: =IFERROR(VLOOKUP($A6,IS!$A$1:$F$27,E$2,FALSE),"") | F6: =IFERROR(VLOOKUP($A6,IS!$A$1:$F$27,F$2,FALSE),"")
A7: =IS!A6 | B7: =IFERROR(VLOOKUP($A7,IS!$A$1:$F$27,B$2,FALSE),"") | C7: =IFERROR(VLOOKUP($A7,IS!$A$1:$F$27,C$2,FALSE),"") | D7: =IFERROR(VLOOKUP($A7,IS!$A$1:$F$27,D$2,FALSE),"") | E7: =IFERROR(VLOOKUP($A7,IS!$A$1:$F$27,E$2,FALSE),"") | F7: =IFERROR(VLOOKUP($A7,IS!$A$1:$F$27,F$2,FALSE),"")
A8: =IS!A7 | B8: =IFERROR(VLOOKUP($A8,IS!$A$1:$F$27,B$2,FALSE),"") | C8: =IFERROR(VLOOKUP($A8,IS!$A$1:$F$27,C$2,FALSE),"") | D8: =IFERROR(VLOOKUP($A8,IS!$A$1:$F$27,D$2,FALSE),"") | E8: =IFERROR(VLOOKUP($A8,IS!$A$1:$F$27,E$2,FALSE),"") | F8: =IFERROR(VLOOKUP($A8,IS!$A$1:$F$27,F$2,FALSE),"")
A9: =IS!A8 | B9: =IFERROR(VLOOKUP($A9,IS!$A$1:$F$27,B$2,FALSE),"") | C9: =IFERROR(VLOOKUP($A9,IS!$A$1:$F$27,C$2,FALSE),"") | D9: =IFERROR(VLOOKUP($A9,IS!$A$1:$F$27,D$2,FALSE),"") | E9: =IFERROR(VLOOKUP($A9,IS!$A$1:$F$27,E$2,FALSE),"") | F9: =IFERROR(VLOOKUP($A9,IS!$A$1:$F$27,F$2,FALSE),"")
A10: =IS!A9
A11: =IS!A10 | B11: =IFERROR(VLOOKUP($A11,IS!$A$1:$F$27,B$2,FALSE),"") | C11: =IFERROR(VLOOKUP($A11,IS!$A$1:$F$27,C$2,FALSE),"") | D11: =IFERROR(VLOOKUP($A11,IS!$A$1:$F$27,D$2,FALSE),"") | E11: =IFERROR(VLOOKUP($A11,IS!$A$1:$F$27,E$2,FALSE),"") | F11: =IFERROR(VLOOKUP($A11,IS!$A$1:$F$27,F$2,FALSE),"")
A12: =IS!A11 | B12: =IFERROR(VLOOKUP($A12,IS!$A$1:$F$27,B$2,FALSE),"") | C12: =IFERROR(VLOOKUP($A12,IS!$A$1:$F$27,C$2,FALSE),"") | D12: =IFERROR(VLOOKUP($A12,IS!$A$1:$F$27,D$2,FALSE),"") | E12: =IFERROR(VLOOKUP($A12,IS!$A$1:$F$27,E$2,FALSE),"") | F12: =IFERROR(VLOOKUP($A12,IS!$A$1:$F$27,F$2,FALSE),"")
A13: =IS!A12 | B13: =IFERROR(VLOOKUP($A13,IS!$A$1:$F$27,B$2,FALSE),"") | C13: =IFERROR(VLOOKUP($A13,IS!$A$1:$F$27,C$2,FALSE),"") | D13: =IFERROR(VLOOKUP($A13,IS!$A$1:$F$27,D$2,FALSE),"") | E13: =IFERROR(VLOOKUP($A13,IS!$A$1:$F$27,E$2,FALSE),"") | F13: =IFERROR(VLOOKUP($A13,IS!$A$1:$F$27,F$2,FALSE),"")
A14: =IS!A13 | B14: =IFERROR(VLOOKUP($A14,IS!$A$1:$F$27,B$2,FALSE),"") | C14: =IFERROR(VLOOKUP($A14,IS!$A$1:$F$27,C$2,FALSE),"") | D14: =IFERROR(VLOOKUP($A14,IS!$A$1:$F$27,D$2,FALSE),"") | E14: =IFERROR(VLOOKUP($A14,IS!$A$1:$F$27,E$2,FALSE),"") | F14: =IFERROR(VLOOKUP($A14,IS!$A$1:$F$27,F$2,FALSE),"")
A15: =IS!A14 | B15: =IFERROR(VLOOKUP($A15,IS!$A$1:$F$27,B$2,FALSE),"") | C15: =IFERROR(VLOOKUP($A15,IS!$A$1:$F$27,C$2,FALSE),"") | D15: =IFERROR(VLOOKUP($A15,IS!$A$1:$F$27,D$2,FALSE),"") | E15: =IFERROR(VLOOKUP($A15,IS!$A$1:$F$27,E$2,FALSE),"") | F15: =IFERROR(VLOOKUP($A15,IS!$A$1:$F$27,F$2,FALSE),"")
A16: =IS!A15 | B16: =IFERROR(VLOOKUP($A16,IS!$A$1:$F$27,B$2,FALSE),"") | C16: =IFERROR(VLOOKUP($A16,IS!$A$1:$F$27,C$2,FALSE),"") | D16: =IFERROR(VLOOKUP($A16,IS!$A$1:$F$27,D$2,FALSE),"") | E16: =IFERROR(VLOOKUP($A16,IS!$A$1:$F$27,E$2,FALSE),"") | F16: =IFERROR(VLOOKUP($A16,IS!$A$1:$F$27,F$2,FALSE),"")
A17: =IS!A16 | B17: =IFERROR(VLOOKUP($A17,IS!$A$1:$F$27,B$2,FALSE),"") | C17: =IFERROR(VLOOKUP($A17,IS!$A$1:$F$27,C$2,FALSE),"") | D17: =IFERROR(VLOOKUP($A17,IS!$A$1:$F$27,D$2,FALSE),"") | E17: =IFERROR(VLOOKUP($A17,IS!$A$1:$F$27,E$2,FALSE),"") | F17: =IFERROR(VLOOKUP($A17,IS!$A$1:$F$27,F$2,FALSE),"")
A18: =IS!A17 | B18: =IFERROR(VLOOKUP($A18,IS!$A$1:$F$27,B$2,FALSE),"") | C18: =IFERROR(VLOOKUP($A18,IS!$A$1:$F$27,C$2,FALSE),"") | D18: =IFERROR(VLOOKUP($A18,IS!$A$1:$F$27,D$2,FALSE),"") | E18: =IFERROR(VLOOKUP($A18,IS!$A$1:$F$27,E$2,FALSE),"") | F18: =IFERROR(VLOOKUP($A18,IS!$A$1:$F$27,F$2,FALSE),"")
A19: =IS!A18 | B19: =IFERROR(VLOOKUP($A19,IS!$A$1:$F$27,B$2,FALSE),"") | C19: =IFERROR(VLOOKUP($A19,IS!$A$1:$F$27,C$2,FALSE),"") | D19: =IFERROR(VLOOKUP($A19,IS!$A$1:$F$27,D$2,FALSE),"") | E19: =IFERROR(VLOOKUP($A19,IS!$A$1:$F$27,E$2,FALSE),"") | F19: =IFERROR(VLOOKUP($A19,IS!$A$1:$F$27,F$2,FALSE),"")
A20: =IS!A19 | B20: =IFERROR(VLOOKUP($A20,IS!$A$1:$F$27,B$2,FALSE),"") | C20: =IFERROR(VLOOKUP($A20,IS!$A$1:$F$27,C$2,FALSE),"") | D20: =IFERROR(VLOOKUP($A20,IS!$A$1:$F$27,D$2,FALSE),"") | E20: =IFERROR(VLOOKUP($A20,IS!$A$1:$F$27,E$2,FALSE),"") | F20: =IFERROR(VLOOKUP($A20,IS!$A$1:$F$27,F$2,FALSE),"")
A21: =IS!A20 | B21: =IFERROR(VLOOKUP($A21,IS!$A$1:$F$27,B$2,FALSE),"") | C21: =IFERROR(VLOOKUP($A21,IS!$A$1:$F$27,C$2,FALSE),"") | D21: =IFERROR(VLOOKUP($A21,IS!$A$1:$F$27,D$2,FALSE),"") | E21: =IFERROR(VLOOKUP($A21,IS!$A$1:$F$27,E$2,FALSE),"") | F21: =IFERROR(VLOOKUP($A21,IS!$A$1:$F$27,F$2,FALSE),"")
A22: =IS!A21 | B22: =IFERROR(VLOOKUP($A22,IS!$A$1:$F$27,B$2,FALSE),"") | C22: =IFERROR(VLOOKUP($A22,IS!$A$1:$F$27,C$2,FALSE),"") | D22: =IFERROR(VLOOKUP($A22,IS!$A$1:$F$27,D$2,FALSE),"") | E22: =IFERROR(VLOOKUP($A22,IS!$A$1:$F$27,E$2,FALSE),"") | F22: =IFERROR(VLOOKUP($A22,IS!$A$1:$F$27,F$2,FALSE),"")
... A28: =IS!A27 | B28: =IFERROR(VLOOKUP($A28,IS!$A$1:$F$27,B$2,FALSE),"") | C28: =IFERROR(VLOOKUP($A28,IS!$A$1:$F$27,C$2,FALSE),"") | D28: =IFERROR(VLOOKUP($A28,IS!$A$1:$F$27,D$2,FALSE),"") | E28: =IFERROR(VLOOKUP($A28,IS!$A$1:$F$27,E$2,FALSE),"") | F28: =IFERROR(VLOOKUP($A28,IS!$A$1:$F$27,F$2,FALSE),"")

Sheet IS_COMP
A1: =IS!A1 | B1: comparative Income Statement
A2: =IS!A2 | B2: =IS!B2 | C2: =IS!C2 | D2: =IS!D2 | E2: =IS!E2 | F2: Trend
A3: =IS!A3
A4: =IS!A4 | B4: =IFERROR((_xlfn.XLOOKUP($A4,IS!$A$1:$A$27,IS!B$1:B$27," ",0,1)/_xlfn.XLOOKUP($A4,IS!$A$1:$A$27,IS!C$1:C$27," ",0,1)) -1,"") | C4: =IFERROR((_xlfn.XLOOKUP($A4,IS!$A$1:$A$27,IS!C$1:C$27," ",0,1)/_xlfn.XLOOKUP($A4,IS!$A$1:$A$27,IS!D$1:D$27," ",0,1)) -1,"") | D4: =IFERROR((_xlfn.XLOOKUP($A4,IS!$A$1:$A$27,IS!D$1:D$27," ",0,1)/_xlfn.XLOOKUP($A4,IS!$A$1:$A$27,IS!E$1:E$27," ",0,1)) -1,"") | E4: =IFERROR((_xlfn.XLOOKUP($A4,IS!$A$1:$A$27,IS!E$1:E$27," ",0,1)/_xlfn.XLOOKUP($A4,IS!$A$1:$A$27,IS!F$1:F$27," ",0,1)) -1,"")
A5: =IS!A5 | B5: =IFERROR((_xlfn.XLOOKUP($A5,IS!$A$1:$A$27,IS!B$1:B$27," ",0,1)/_xlfn.XLOOKUP($A5,IS!$A$1:$A$27,IS!C$1:C$27," ",0,1)) -1,"") | C5: =IFERROR((_xlfn.XLOOKUP($A5,IS!$A$1:$A$27,IS!C$1:C$27," ",0,1)/_xlfn.XLOOKUP($A5,IS!$A$1:$A$27,IS!D$1:D$27," ",0,1)) -1,"") | D5: =IFERROR((_xlfn.XLOOKUP($A5,IS!$A$1:$A$27,IS!D$1:D$27," ",0,1)/_xlfn.XLOOKUP($A5,IS!$A$1:$A$27,IS!E$1:E$27," ",0,1)) -1,"") | E5: =IFERROR((_xlfn.XLOOKUP($A5,IS!$A$1:$A$27,IS!E$1:E$27," ",0,1)/_xlfn.XLOOKUP($A5,IS!$A$1:$A$27,IS!F$1:F$27," ",0,1)) -1,"")
A6: =IS!A6 | B6: =IFERROR((_xlfn.XLOOKUP($A6,IS!$A$1:$A$27,IS!B$1:B$27," ",0,1)/_xlfn.XLOOKUP($A6,IS!$A$1:$A$27,IS!C$1:C$27," ",0,1)) -1,"") | C6: =IFERROR((_xlfn.XLOOKUP($A6,IS!$A$1:$A$27,IS!C$1:C$27," ",0,1)/_xlfn.XLOOKUP($A6,IS!$A$1:$A$27,IS!D$1:D$27," ",0,1)) -1,"") | D6: =IFERROR((_xlfn.XLOOKUP($A6,IS!$A$1:$A$27,IS!D$1:D$27," ",0,1)/_xlfn.XLOOKUP($A6,IS!$A$1:$A$27,IS!E$1:E$27," ",0,1)) -1,"") | E6: =IFERROR((_xlfn.XLOOKUP($A6,IS!$A$1:$A$27,IS!E$1:E$27," ",0,1)/_xlfn.XLOOKUP($A6,IS!$A$1:$A$27,IS!F$1:F$27," ",0,1)) -1,"")
A7: =IS!A7 | B7: =IFERROR((_xlfn.XLOOKUP($A7,IS!$A$1:$A$27,IS!B$1:B$27," ",0,1)/_xlfn.XLOOKUP($A7,IS!$A$1:$A$27,IS!C$1:C$27," ",0,1)) -1,"") | C7: =IFERROR((_xlfn.XLOOKUP($A7,IS!$A$1:$A$27,IS!C$1:C$27," ",0,1)/_xlfn.XLOOKUP($A7,IS!$A$1:$A$27,IS!D$1:D$27," ",0,1)) -1,"") | D7: =IFERROR((_xlfn.XLOOKUP($A7,IS!$A$1:$A$27,IS!D$1:D$27," ",0,1)/_xlfn.XLOOKUP($A7,IS!$A$1:$A$27,IS!E$1:E$27," ",0,1)) -1,"") | E7: =IFERROR((_xlfn.XLOOKUP($A7,IS!$A$1:$A$27,IS!E$1:E$27," ",0,1)/_xlfn.XLOOKUP($A7,IS!$A$1:$A$27,IS!F$1:F$27," ",0,1)) -1,"")
A8: =IS!A8 | B8: =IFERROR((_xlfn.XLOOKUP($A8,IS!$A$1:$A$27,IS!B$1:B$27," ",0,1)/_xlfn.XLOOKUP($A8,IS!$A$1:$A$27,IS!C$1:C$27," ",0,1)) -1,"") | C8: =IFERROR((_xlfn.XLOOKUP($A8,IS!$A$1:$A$27,IS!C$1:C$27," ",0,1)/_xlfn.XLOOKUP($A8,IS!$A$1:$A$27,IS!D$1:D$27," ",0,1)) -1,"") | D8: =IFERROR((_xlfn.XLOOKUP($A8,IS!$A$1:$A$27,IS!D$1:D$27," ",0,1)/_xlfn.XLOOKUP($A8,IS!$A$1:$A$27,IS!E$1:E$27," ",0,1)) -1,"") | E8: =IFERROR((_xlfn.XLOOKUP($A8,IS!$A$1:$A$27,IS!E$1:E$27," ",0,1)/_xlfn.XLOOKUP($A8,IS!$A$1:$A$27,IS!F$1:F$27," ",0,1)) -1,"")
A9: =IS!A9 | B9: =IFERROR((_xlfn.XLOOKUP($A9,IS!$A$1:$A$27,IS!B$1:B$27," ",0,1)/_xlfn.XLOOKUP($A9,IS!$A$1:$A$27,IS!C$1:C$27," ",0,1)) -1,"") | C9: =IFERROR((_xlfn.XLOOKUP($A9,IS!$A$1:$A$27,IS!C$1:C$27," ",0,1)/_xlfn.XLOOKUP($A9,IS!$A$1:$A$27,IS!D$1:D$27," ",0,1)) -1,"") | D9: =IFERROR((_xlfn.XLOOKUP($A9,IS!$A$1:$A$27,IS!D$1:D$27," ",0,1)/_xlfn.XLOOKUP($A9,IS!$A$1:$A$27,IS!E$1:E$27," ",0,1)) -1,"") | E9: =IFERROR((_xlfn.XLOOKUP($A9,IS!$A$1:$A$27,IS!E$1:E$27," ",0,1)/_xlfn.XLOOKUP($A9,IS!$A$1:$A$27,IS!F$1:F$27," ",0,1)) -1,"")
A10: =IS!A10 | B10: =IFERROR((_xlfn.XLOOKUP($A10,IS!$A$1:$A$27,IS!B$1:B$27," ",0,1)/_xlfn.XLOOKUP($A10,IS!$A$1:$A$27,IS!C$1:C$27," ",0,1)) -1,"") | C10: =IFERROR((_xlfn.XLOOKUP($A10,IS!$A$1:$A$27,IS!C$1:C$27," ",0,1)/_xlfn.XLOOKUP($A10,IS!$A$1:$A$27,IS!D$1:D$27," ",0,1)) -1,"") | D10: =IFERROR((_xlfn.XLOOKUP($A10,IS!$A$1:$A$27,IS!D$1:D$27," ",0,1)/_xlfn.XLOOKUP($A10,IS!$A$1:$A$27,IS!E$1:E$27," ",0,1)) -1,"") | E10: =IFERROR((_xlfn.XLOOKUP($A10,IS!$A$1:$A$27,IS!E$1:E$27," ",0,1)/_xlfn.XLOOKUP($A10,IS!$A$1:$A$27,IS!F$1:F$27," ",0,1)) -1,"")
A11: =IS!A11 | B11: =IFERROR((_xlfn.XLOOKUP($A11,IS!$A$1:$A$27,IS!B$1:B$27," ",0,1)/_xlfn.XLOOKUP($A11,IS!$A$1:$A$27,IS!C$1:C$27," ",0,1)) -1,"") | C11: =IFERROR((_xlfn.XLOOKUP($A11,IS!$A$1:$A$27,IS!C$1:C$27," ",0,1)/_xlfn.XLOOKUP($A11,IS!$A$1:$A$27,IS!D$1:D$27," ",0,1)) -1,"") | D11: =IFERROR((_xlfn.XLOOKUP($A11,IS!$A$1:$A$27,IS!D$1:D$27," ",0,1)/_xlfn.XLOOKUP($A11,IS!$A$1:$A$27,IS!E$1:E$27," ",0,1)) -1,"") | E11: =IFERROR((_xlfn.XLOOKUP($A11,IS!$A$1:$A$27,IS!E$1:E$27," ",0,1)/_xlfn.XLOOKUP($A11,IS!$A$1:$A$27,IS!F$1:F$27," ",0,1)) -1,"")
A12: =IS!A12 | B12: =IFERROR((_xlfn.XLOOKUP($A12,IS!$A$1:$A$27,IS!B$1:B$27," ",0,1)/_xlfn.XLOOKUP($A12,IS!$A$1:$A$27,IS!C$1:C$27," ",0,1)) -1,"") | C12: =IFERROR((_xlfn.XLOOKUP($A12,IS!$A$1:$A$27,IS!C$1:C$27," ",0,1)/_xlfn.XLOOKUP($A12,IS!$A$1:$A$27,IS!D$1:D$27," ",0,1)) -1,"") | D12: =IFERROR((_xlfn.XLOOKUP($A12,IS!$A$1:$A$27,IS!D$1:D$27," ",0,1)/_xlfn.XLOOKUP($A12,IS!$A$1:$A$27,IS!E$1:E$27," ",0,1)) -1,"") | E12: =IFERROR((_xlfn.XLOOKUP($A12,IS!$A$1:$A$27,IS!E$1:E$27," ",0,1)/_xlfn.XLOOKUP($A12,IS!$A$1:$A$27,IS!F$1:F$27," ",0,1)) -1,"")
A13: =IS!A13 | B13: =IFERROR((_xlfn.XLOOKUP($A13,IS!$A$1:$A$27,IS!B$1:B$27," ",0,1)/_xlfn.XLOOKUP($A13,IS!$A$1:$A$27,IS!C$1:C$27," ",0,1)) -1,"") | C13: =IFERROR((_xlfn.XLOOKUP($A13,IS!$A$1:$A$27,IS!C$1:C$27," ",0,1)/_xlfn.XLOOKUP($A13,IS!$A$1:$A$27,IS!D$1:D$27," ",0,1)) -1,"") | D13: =IFERROR((_xlfn.XLOOKUP($A13,IS!$A$1:$A$27,IS!D$1:D$27," ",0,1)/_xlfn.XLOOKUP($A13,IS!$A$1:$A$27,IS!E$1:E$27," ",0,1)) -1,"") | E13: =IFERROR((_xlfn.XLOOKUP($A13,IS!$A$1:$A$27,IS!E$1:E$27," ",0,1)/_xlfn.XLOOKUP($A13,IS!$A$1:$A$27,IS!F$1:F$27," ",0,1)) -1,"")
A14: =IS!A14 | B14: =IFERROR((_xlfn.XLOOKUP($A14,IS!$A$1:$A$27,IS!B$1:B$27," ",0,1)/_xlfn.XLOOKUP($A14,IS!$A$1:$A$27,IS!C$1:C$27," ",0,1)) -1,"") | C14: =IFERROR((_xlfn.XLOOKUP($A14,IS!$A$1:$A$27,IS!C$1:C$27," ",0,1)/_xlfn.XLOOKUP($A14,IS!$A$1:$A$27,IS!D$1:D$27," ",0,1)) -1,"") | D14: =IFERROR((_xlfn.XLOOKUP($A14,IS!$A$1:$A$27,IS!D$1:D$27," ",0,1)/_xlfn.XLOOKUP($A14,IS!$A$1:$A$27,IS!E$1:E$27," ",0,1)) -1,"") | E14: =IFERROR((_xlfn.XLOOKUP($A14,IS!$A$1:$A$27,IS!E$1:E$27," ",0,1)/_xlfn.XLOOKUP($A14,IS!$A$1:$A$27,IS!F$1:F$27," ",0,1)) -1,"")
A15: =IS!A15 | B15: =IFERROR((_xlfn.XLOOKUP($A15,IS!$A$1:$A$27,IS!B$1:B$27," ",0,1)/_xlfn.XLOOKUP($A15,IS!$A$1:$A$27,IS!C$1:C$27," ",0,1)) -1,"") | C15: =IFERROR((_xlfn.XLOOKUP($A15,IS!$A$1:$A$27,IS!C$1:C$27," ",0,1)/_xlfn.XLOOKUP($A15,IS!$A$1:$A$27,IS!D$1:D$27," ",0,1)) -1,"") | D15: =IFERROR((_xlfn.XLOOKUP($A15,IS!$A$1:$A$27,IS!D$1:D$27," ",0,1)/_xlfn.XLOOKUP($A15,IS!$A$1:$A$27,IS!E$1:E$27," ",0,1)) -1,"") | E15: =IFERROR((_xlfn.XLOOKUP($A15,IS!$A$1:$A$27,IS!E$1:E$27," ",0,1)/_xlfn.XLOOKUP($A15,IS!$A$1:$A$27,IS!F$1:F$27," ",0,1)) -1,"")
... A27: =IS!A27 | B27: =IFERROR((_xlfn.XLOOKUP($A27,IS!$A$1:$A$27,IS!B$1:B$27," ",0,1)/_xlfn.XLOOKUP($A27,IS!$A$1:$A$27,IS!C$1:C$27," ",0,1)) -1,"") | C27: =IFERROR((_xlfn.XLOOKUP($A27,IS!$A$1:$A$27,IS!C$1:C$27," ",0,1)/_xlfn.XLOOKUP($A27,IS!$A$1:$A$27,IS!D$1:D$27," ",0,1)) -1,"") | D27: =IFERROR((_xlfn.XLOOKUP($A27,IS!$A$1:$A$27,IS!D$1:D$27," ",0,1)/_xlfn.XLOOKUP($A27,IS!$A$1:$A$27,IS!E$1:E$27," ",0,1)) -1,"") | E27: =IFERROR((_xlfn.XLOOKUP($A27,IS!$A$1:$A$27,IS!E$1:E$27," ",0,1)/_xlfn.XLOOKUP($A27,IS!$A$1:$A$27,IS!F$1:F$27," ",0,1)) -1,"")

Sheet BS_COMP
A1: =BS!A1
A2: =BS!A2 | B2: =BS!B2 | C2: =BS!C2 | D2: =BS!D2 | E2: =BS!E2 | F2: =BS!F2
A3: =BS!A3
A4: =BS!A4 | B4: =IFERROR(_xlfn.XLOOKUP($A4,BS!$A$1:$A$36,BS!B$1:B$36,"",0,1)/_xlfn.XLOOKUP($A4,BS!$A$1:$A$36,BS!C$1:C$36,"",0,1)-1,"") | C4: =IFERROR(_xlfn.XLOOKUP($A4,BS!$A$1:$A$36,BS!C$1:C$36,"",0,1)/_xlfn.XLOOKUP($A4,BS!$A$1:$A$36,BS!D$1:D$36,"",0,1)-1,"") | D4: =IFERROR(_xlfn.XLOOKUP($A4,BS!$A$1:$A$36,BS!D$1:D$36,"",0,1)/_xlfn.XLOOKUP($A4,BS!$A$1:$A$36,BS!E$1:E$36,"",0,1)-1,"") | E4: =IFERROR(_xlfn.XLOOKUP($A4,BS!$A$1:$A$36,BS!E$1:E$36,"",0,1)/_xlfn.XLOOKUP($A4,BS!$A$1:$A$36,BS!F$1:F$36,"",0,1)-1,"")
A5: =BS!A5 | B5: =IFERROR(_xlfn.XLOOKUP($A5,BS!$A$1:$A$36,BS!B$1:B$36,"",0,1)/_xlfn.XLOOKUP($A5,BS!$A$1:$A$36,BS!C$1:C$36,"",0,1)-1,"") | C5: =IFERROR(_xlfn.XLOOKUP($A5,BS!$A$1:$A$36,BS!C$1:C$36,"",0,1)/_xlfn.XLOOKUP($A5,BS!$A$1:$A$36,BS!D$1:D$36,"",0,1)-1,"") | D5: =IFERROR(_xlfn.XLOOKUP($A5,BS!$A$1:$A$36,BS!D$1:D$36,"",0,1)/_xlfn.XLOOKUP($A5,BS!$A$1:$A$36,BS!E$1:E$36,"",0,1)-1,"") | E5: =IFERROR(_xlfn.XLOOKUP($A5,BS!$A$1:$A$36,BS!E$1:E$36,"",0,1)/_xlfn.XLOOKUP($A5,BS!$A$1:$A$36,BS!F$1:F$36,"",0,1)-1,"")
A6: =BS!A6 | B6: =IFERROR(_xlfn.XLOOKUP($A6,BS!$A$1:$A$36,BS!B$1:B$36,"",0,1)/_xlfn.XLOOKUP($A6,BS!$A$1:$A$36,BS!C$1:C$36,"",0,1)-1,"") | C6: =IFERROR(_xlfn.XLOOKUP($A6,BS!$A$1:$A$36,BS!C$1:C$36,"",0,1)/_xlfn.XLOOKUP($A6,BS!$A$1:$A$36,BS!D$1:D$36,"",0,1)-1,"") | D6: =IFERROR(_xlfn.XLOOKUP($A6,BS!$A$1:$A$36,BS!D$1:D$36,"",0,1)/_xlfn.XLOOKUP($A6,BS!$A$1:$A$36,BS!E$1:E$36,"",0,1)-1,"") | E6: =IFERROR(_xlfn.XLOOKUP($A6,BS!$A$1:$A$36,BS!E$1:E$36,"",0,1)/_xlfn.XLOOKUP($A6,BS!$A$1:$A$36,BS!F$1:F$36,"",0,1)-1,"")
A7: =BS!A7 | B7: =IFERROR(_xlfn.XLOOKUP($A7,BS!$A$1:$A$36,BS!B$1:B$36,"",0,1)/_xlfn.XLOOKUP($A7,BS!$A$1:$A$36,BS!C$1:C$36,"",0,1)-1,"") | C7: =IFERROR(_xlfn.XLOOKUP($A7,BS!$A$1:$A$36,BS!C$1:C$36,"",0,1)/_xlfn.XLOOKUP($A7,BS!$A$1:$A$36,BS!D$1:D$36,"",0,1)-1,"") | D7: =IFERROR(_xlfn.XLOOKUP($A7,BS!$A$1:$A$36,BS!D$1:D$36,"",0,1)/_xlfn.XLOOKUP($A7,BS!$A$1:$A$36,BS!E$1:E$36,"",0,1)-1,"") | E7: =IFERROR(_xlfn.XLOOKUP($A7,BS!$A$1:$A$36,BS!E$1:E$36,"",0,1)/_xlfn.XLOOKUP($A7,BS!$A$1:$A$36,BS!F$1:F$36,"",0,1)-1,"")
A8: =BS!A8 | B8: =IFERROR(_xlfn.XLOOKUP($A8,BS!$A$1:$A$36,BS!B$1:B$36,"",0,1)/_xlfn.XLOOKUP($A8,BS!$A$1:$A$36,BS!C$1:C$36,"",0,1)-1,"") | C8: =IFERROR(_xlfn.XLOOKUP($A8,BS!$A$1:$A$36,BS!C$1:C$36,"",0,1)/_xlfn.XLOOKUP($A8,BS!$A$1:$A$36,BS!D$1:D$36,"",0,1)-1,"") | D8: =IFERROR(_xlfn.XLOOKUP($A8,BS!$A$1:$A$36,BS!D$1:D$36,"",0,1)/_xlfn.XLOOKUP($A8,BS!$A$1:$A$36,BS!E$1:E$36,"",0,1)-1,"") | E8: =IFERROR(_xlfn.XLOOKUP($A8,BS!$A$1:$A$36,BS!E$1:E$36,"",0,1)/_xlfn.XLOOKUP($A8,BS!$A$1:$A$36,BS!F$1:F$36,"",0,1)-1,"")
A9: =BS!A9 | B9: =IFERROR(_xlfn.XLOOKUP($A9,BS!$A$1:$A$36,BS!B$1:B$36,"",0,1)/_xlfn.XLOOKUP($A9,BS!$A$1:$A$36,BS!C$1:C$36,"",0,1)-1,"") | C9: =IFERROR(_xlfn.XLOOKUP($A9,BS!$A$1:$A$36,BS!C$1:C$36,"",0,1)/_xlfn.XLOOKUP($A9,BS!$A$1:$A$36,BS!D$1:D$36,"",0,1)-1,"") | D9: =IFERROR(_xlfn.XLOOKUP($A9,BS!$A$1:$A$36,BS!D$1:D$36,"",0,1)/_xlfn.XLOOKUP($A9,BS!$A$1:$A$36,BS!E$1:E$36,"",0,1)-1,"") | E9: =IFERROR(_xlfn.XLOOKUP($A9,BS!$A$1:$A$36,BS!E$1:E$36,"",0,1)/_xlfn.XLOOKUP($A9,BS!$A$1:$A$36,BS!F$1:F$36,"",0,1)-1,"")
A10: =BS!A10 | B10: =IFERROR(_xlfn.XLOOKUP($A10,BS!$A$1:$A$36,BS!B$1:B$36,"",0,1)/_xlfn.XLOOKUP($A10,BS!$A$1:$A$36,BS!C$1:C$36,"",0,1)-1,"") | C10: =IFERROR(_xlfn.XLOOKUP($A10,BS!$A$1:$A$36,BS!C$1:C$36,"",0,1)/_xlfn.XLOOKUP($A10,BS!$A$1:$A$36,BS!D$1:D$36,"",0,1)-1,"") | D10: =IFERROR(_xlfn.XLOOKUP($A10,BS!$A$1:$A$36,BS!D$1:D$36,"",0,1)/_xlfn.XLOOKUP($A10,BS!$A$1:$A$36,BS!E$1:E$36,"",0,1)-1,"") | E10: =IFERROR(_xlfn.XLOOKUP($A10,BS!$A$1:$A$36,BS!E$1:E$36,"",0,1)/_xlfn.XLOOKUP($A10,BS!$A$1:$A$36,BS!F$1:F$36,"",0,1)-1,"")
A11: =BS!A11 | B11: =IFERROR(_xlfn.XLOOKUP($A11,BS!$A$1:$A$36,BS!B$1:B$36,"",0,1)/_xlfn.XLOOKUP($A11,BS!$A$1:$A$36,BS!C$1:C$36,"",0,1)-1,"") | C11: =IFERROR(_xlfn.XLOOKUP($A11,BS!$A$1:$A$36,BS!C$1:C$36,"",0,1)/_xlfn.XLOOKUP($A11,BS!$A$1:$A$36,BS!D$1:D$36,"",0,1)-1,"") | D11: =IFERROR(_xlfn.XLOOKUP($A11,BS!$A$1:$A$36,BS!D$1:D$36,"",0,1)/_xlfn.XLOOKUP($A11,BS!$A$1:$A$36,BS!E$1:E$36,"",0,1)-1,"") | E11: =IFERROR(_xlfn.XLOOKUP($A11,BS!$A$1:$A$36,BS!E$1:E$36,"",0,1)/_xlfn.XLOOKUP($A11,BS!$A$1:$A$36,BS!F$1:F$36,"",0,1)-1,"")
A12: =BS!A12 | B12: =IFERROR(_xlfn.XLOOKUP($A12,BS!$A$1:$A$36,BS!B$1:B$36,"",0,1)/_xlfn.XLOOKUP($A12,BS!$A$1:$A$36,BS!C$1:C$36,"",0,1)-1,"") | C12: =IFERROR(_xlfn.XLOOKUP($A12,BS!$A$1:$A$36,BS!C$1:C$36,"",0,1)/_xlfn.XLOOKUP($A12,BS!$A$1:$A$36,BS!D$1:D$36,"",0,1)-1,"") | D12: =IFERROR(_xlfn.XLOOKUP($A12,BS!$A$1:$A$36,BS!D$1:D$36,"",0,1)/_xlfn.XLOOKUP($A12,BS!$A$1:$A$36,BS!E$1:E$36,"",0,1)-1,"") | E12: =IFERROR(_xlfn.XLOOKUP($A12,BS!$A$1:$A$36,BS!E$1:E$36,"",0,1)/_xlfn.XLOOKUP($A12,BS!$A$1:$A$36,BS!F$1:F$36,"",0,1)-1,"")
A13: =BS!A13 | B13: =IFERROR(_xlfn.XLOOKUP($A13,BS!$A$1:$A$36,BS!B$1:B$36,"",0,1)/_xlfn.XLOOKUP($A13,BS!$A$1:$A$36,BS!C$1:C$36,"",0,1)-1,"") | C13: =IFERROR(_xlfn.XLOOKUP($A13,BS!$A$1:$A$36,BS!C$1:C$36,"",0,1)/_xlfn.XLOOKUP($A13,BS!$A$1:$A$36,BS!D$1:D$36,"",0,1)-1,"") | D13: =IFERROR(_xlfn.XLOOKUP($A13,BS!$A$1:$A$36,BS!D$1:D$36,"",0,1)/_xlfn.XLOOKUP($A13,BS!$A$1:$A$36,BS!E$1:E$36,"",0,1)-1,"") | E13: =IFERROR(_xlfn.XLOOKUP($A13,BS!$A$1:$A$36,BS!E$1:E$36,"",0,1)/_xlfn.XLOOKUP($A13,BS!$A$1:$A$36,BS!F$1:F$36,"",0,1)-1,"")
A14: =BS!A14 | B14: =IFERROR(_xlfn.XLOOKUP($A14,BS!$A$1:$A$36,BS!B$1:B$36,"",0,1)/_xlfn.XLOOKUP($A14,BS!$A$1:$A$36,BS!C$1:C$36,"",0,1)-1,"") | C14: =IFERROR(_xlfn.XLOOKUP($A14,BS!$A$1:$A$36,BS!C$1:C$36,"",0,1)/_xlfn.XLOOKUP($A14,BS!$A$1:$A$36,BS!D$1:D$36,"",0,1)-1,"") | D14: =IFERROR(_xlfn.XLOOKUP($A14,BS!$A$1:$A$36,BS!D$1:D$36,"",0,1)/_xlfn.XLOOKUP($A14,BS!$A$1:$A$36,BS!E$1:E$36,"",0,1)-1,"") | E14: =IFERROR(_xlfn.XLOOKUP($A14,BS!$A$1:$A$36,BS!E$1:E$36,"",0,1)/_xlfn.XLOOKUP($A14,BS!$A$1:$A$36,BS!F$1:F$36,"",0,1)-1,"")
A15: =BS!A15 | B15: =IFERROR(_xlfn.XLOOKUP($A15,BS!$A$1:$A$36,BS!B$1:B$36,"",0,1)/_xlfn.XLOOKUP($A15,BS!$A$1:$A$36,BS!C$1:C$36,"",0,1)-1,"") | C15: =IFERROR(_xlfn.XLOOKUP($A15,BS!$A$1:$A$36,BS!C$1:C$36,"",0,1)/_xlfn.XLOOKUP($A15,BS!$A$1:$A$36,BS!D$1:D$36,"",0,1)-1,"") | D15: =IFERROR(_xlfn.XLOOKUP($A15,BS!$A$1:$A$36,BS!D$1:D$36,"",0,1)/_xlfn.XLOOKUP($A15,BS!$A$1:$A$36,BS!E$1:E$36,"",0,1)-1,"") | E15: =IFERROR(_xlfn.XLOOKUP($A15,BS!$A$1:$A$36,BS!E$1:E$36,"",0,1)/_xlfn.XLOOKUP($A15,BS!$A$1:$A$36,BS!F$1:F$36,"",0,1)-1,"")
... A20: =BS!A20 | B20: =IFERROR(_xlfn.XLOOKUP($A20,BS!$A$1:$A$36,BS!B$1:B$36,"",0,1)/_xlfn.XLOOKUP($A20,BS!$A$1:$A$36,BS!C$1:C$36,"",0,1)-1,"") | C20: =IFERROR(_xlfn.XLOOKUP($A20,BS!$A$1:$A$36,BS!C$1:C$36,"",0,1)/_xlfn.XLOOKUP($A20,BS!$A$1:$A$36,BS!D$1:D$36,"",0,1)-1,"") | D20: =IFERROR(_xlfn.XLOOKUP($A20,BS!$A$1:$A$36,BS!D$1:D$36,"",0,1)/_xlfn.XLOOKUP($A20,BS!$A$1:$A$36,BS!E$1:E$36,"",0,1)-1,"") | E20: =IFERROR(_xlfn.XLOOKUP($A20,BS!$A$1:$A$36,BS!E$1:E$36,"",0,1)/_xlfn.XLOOKUP($A20,BS!$A$1:$A$36,BS!F$1:F$36,"",0,1)-1,"")
B21: =IFERROR(_xlfn.XLOOKUP($A21,BS!$A$1:$A$36,BS!B$1:B$36,"",0,1)/_xlfn.XLOOKUP($A21,BS!$A$1:$A$36,BS!C$1:C$36,"",0,1)-1,"") | C21: =IFERROR(_xlfn.XLOOKUP($A21,BS!$A$1:$A$36,BS!C$1:C$36,"",0,1)/_xlfn.XLOOKUP($A21,BS!$A$1:$A$36,BS!D$1:D$36,"",0,1)-1,"") | D21: =IFERROR(_xlfn.XLOOKUP($A21,BS!$A$1:$A$36,BS!D$1:D$36,"",0,1)/_xlfn.XLOOKUP($A21,BS!$A$1:$A$36,BS!E$1:E$36,"",0,1)-1,"") | E21: =IFERROR(_xlfn.XLOOKUP($A21,BS!$A$1:$A$36,BS!E$1:E$36,"",0,1)/_xlfn.XLOOKUP($A21,BS!$A$1:$A$36,BS!F$1:F$36,"",0,1)-1,"")
A22: =BS!A22 | B22: =IFERROR(_xlfn.XLOOKUP($A22,BS!$A$1:$A$36,BS!B$1:B$36,"",0,1)/_xlfn.XLOOKUP($A22,BS!$A$1:$A$36,BS!C$1:C$36,"",0,1)-1,"") | C22: =IFERROR(_xlfn.XLOOKUP($A22,BS!$A$1:$A$36,BS!C$1:C$36,"",0,1)/_xlfn.XLOOKUP($A22,BS!$A$1:$A$36,BS!D$1:D$36,"",0,1)-1,"") | D22: =IFERROR(_xlfn.XLOOKUP($A22,BS!$A$1:$A$36,BS!D$1:D$36,"",0,1)/_xlfn.XLOOKUP($A22,BS!$A$1:$A$36,BS!E$1:E$36,"",0,1)-1,"") | E22: =IFERROR(_xlfn.XLOOKUP($A22,BS!$A$1:$A$36,BS!E$1:E$36,"",0,1)/_xlfn.XLOOKUP($A22,BS!$A$1:$A$36,BS!F$1:F$36,"",0,1)-1,"")
A23: =BS!A23 | B23: =IFERROR(_xlfn.XLOOKUP($A23,BS!$A$1:$A$36,BS!B$1:B$36,"",0,1)/_xlfn.XLOOKUP($A23,BS!$A$1:$A$36,BS!C$1:C$36,"",0,1)-1,"") | C23: =IFERROR(_xlfn.XLOOKUP($A23,BS!$A$1:$A$36,BS!C$1:C$36,"",0,1)/_xlfn.XLOOKUP($A23,BS!$A$1:$A$36,BS!D$1:D$36,"",0,1)-1,"") | D23: =IFERROR(_xlfn.XLOOKUP($A23,BS!$A$1:$A$36,BS!D$1:D$36,"",0,1)/_xlfn.XLOOKUP($A23,BS!$A$1:$A$36,BS!E$1:E$36,"",0,1)-1,"") | E23: =IFERROR(_xlfn.XLOOKUP($A23,BS!$A$1:$A$36,BS!E$1:E$36,"",0,1)/_xlfn.XLOOKUP($A23,BS!$A$1:$A$36,BS!F$1:F$36,"",0,1)-1,"")
A24: =BS!A24 | B24: =IFERROR(_xlfn.XLOOKUP($A24,BS!$A$1:$A$36,BS!B$1:B$36,"",0,1)/_xlfn.XLOOKUP($A24,BS!$A$1:$A$36,BS!C$1:C$36,"",0,1)-1,"") | C24: =IFERROR(_xlfn.XLOOKUP($A24,BS!$A$1:$A$36,BS!C$1:C$36,"",0,1)/_xlfn.XLOOKUP($A24,BS!$A$1:$A$36,BS!D$1:D$36,"",0,1)-1,"") | D24: =IFERROR(_xlfn.XLOOKUP($A24,BS!$A$1:$A$36,BS!D$1:D$36,"",0,1)/_xlfn.XLOOKUP($A24,BS!$A$1:$A$36,BS!E$1:E$36,"",0,1)-1,"") | E24: =IFERROR(_xlfn.XLOOKUP($A24,BS!$A$1:$A$36,BS!E$1:E$36,"",0,1)/_xlfn.XLOOKUP($A24,BS!$A$1:$A$36,BS!F$1:F$36,"",0,1)-1,"")
A25: =BS!A25 | B25: =IFERROR(_xlfn.XLOOKUP($A25,BS!$A$1:$A$36,BS!B$1:B$36,"",0,1)/_xlfn.XLOOKUP($A25,BS!$A$1:$A$36,BS!C$1:C$36,"",0,1)-1,"") | C25: =IFERROR(_xlfn.XLOOKUP($A25,BS!$A$1:$A$36,BS!C$1:C$36,"",0,1)/_xlfn.XLOOKUP($A25,BS!$A$1:$A$36,BS!D$1:D$36,"",0,1)-1,"") | D25: =IFERROR(_xlfn.XLOOKUP($A25,BS!$A$1:$A$36,BS!D$1:D$36,"",0,1)/_xlfn.XLOOKUP($A25,BS!$A$1:$A$36,BS!E$1:E$36,"",0,1)-1,"") | E25: =IFERROR(_xlfn.XLOOKUP($A25,BS!$A$1:$A$36,BS!E$1:E$36,"",0,1)/_xlfn.XLOOKUP($A25,BS!$A$1:$A$36,BS!F$1:F$36,"",0,1)-1,"")
A26: =BS!A26 | B26: =IFERROR(_xlfn.XLOOKUP($A26,BS!$A$1:$A$36,BS!B$1:B$36,"",0,1)/_xlfn.XLOOKUP($A26,BS!$A$1:$A$36,BS!C$1:C$36,"",0,1)-1,"") | C26: =IFERROR(_xlfn.XLOOKUP($A26,BS!$A$1:$A$36,BS!C$1:C$36,"",0,1)/_xlfn.XLOOKUP($A26,BS!$A$1:$A$36,BS!D$1:D$36,"",0,1)-1,"") | D26: =IFERROR(_xlfn.XLOOKUP($A26,BS!$A$1:$A$36,BS!D$1:D$36,"",0,1)/_xlfn.XLOOKUP($A26,BS!$A$1:$A$36,BS!E$1:E$36,"",0,1)-1,"") | E26: =IFERROR(_xlfn.XLOOKUP($A26,BS!$A$1:$A$36,BS!E$1:E$36,"",0,1)/_xlfn.XLOOKUP($A26,BS!$A$1:$A$36,BS!F$1:F$36,"",0,1)-1,"")
A27: =BS!A27 | B27: =IFERROR(_xlfn.XLOOKUP($A27,BS!$A$1:$A$36,BS!B$1:B$36,"",0,1)/_xlfn.XLOOKUP($A27,BS!$A$1:$A$36,BS!C$1:C$36,"",0,1)-1,"") | C27: =IFERROR(_xlfn.XLOOKUP($A27,BS!$A$1:$A$36,BS!C$1:C$36,"",0,1)/_xlfn.XLOOKUP($A27,BS!$A$1:$A$36,BS!D$1:D$36,"",0,1)-1,"") | D27: =IFERROR(_xlfn.XLOOKUP($A27,BS!$A$1:$A$36,BS!D$1:D$36,"",0,1)/_xlfn.XLOOKUP($A27,BS!$A$1:$A$36,BS!E$1:E$36,"",0,1)-1,"") | E27: =IFERROR(_xlfn.XLOOKUP($A27,BS!$A$1:$A$36,BS!E$1:E$36,"",0,1)/_xlfn.XLOOKUP($A27,BS!$A$1:$A$36,BS!F$1:F$36,"",0,1)-1,"")
A28: =BS!A28 | B28: =IFERROR(_xlfn.XLOOKUP($A28,BS!$A$1:$A$36,BS!B$1:B$36,"",0,1)/_xlfn.XLOOKUP($A28,BS!$A$1:$A$36,BS!C$1:C$36,"",0,1)-1,"") | C28: =IFERROR(_xlfn.XLOOKUP($A28,BS!$A$1:$A$36,BS!C$1:C$36,"",0,1)/_xlfn.XLOOKUP($A28,BS!$A$1:$A$36,BS!D$1:D$36,"",0,1)-1,"") | D28: =IFERROR(_xlfn.XLOOKUP($A28,BS!$A$1:$A$36,BS!D$1:D$36,"",0,1)/_xlfn.XLOOKUP($A28,BS!$A$1:$A$36,BS!E$1:E$36,"",0,1)-1,"") | E28: =IFERROR(_xlfn.XLOOKUP($A28,BS!$A$1:$A$36,BS!E$1:E$36,"",0,1)/_xlfn.XLOOKUP($A28,BS!$A$1:$A$36,BS!F$1:F$36,"",0,1)-1,"")
A29: =BS!A29 | B29: =IFERROR(_xlfn.XLOOKUP($A29,BS!$A$1:$A$36,BS!B$1:B$36,"",0,1)/_xlfn.XLOOKUP($A29,BS!$A$1:$A$36,BS!C$1:C$36,"",0,1)-1,"") | C29: =IFERROR(_xlfn.XLOOKUP($A29,BS!$A$1:$A$36,BS!C$1:C$36,"",0,1)/_xlfn.XLOOKUP($A29,BS!$A$1:$A$36,BS!D$1:D$36,"",0,1)-1,"") | D29: =IFERROR(_xlfn.XLOOKUP($A29,BS!$A$1:$A$36,BS!D$1:D$36,"",0,1)/_xlfn.XLOOKUP($A29,BS!$A$1:$A$36,BS!E$1:E$36,"",0,1)-1,"") | E29: =IFERROR(_xlfn.XLOOKUP($A29,BS!$A$1:$A$36,BS!E$1:E$36,"",0,1)/_xlfn.XLOOKUP($A29,BS!$A$1:$A$36,BS!F$1:F$36,"",0,1)-1,"")
A30: =BS!A30 | B30: =IFERROR(_xlfn.XLOOKUP($A30,BS!$A$1:$A$36,BS!B$1:B$36,"",0,1)/_xlfn.XLOOKUP($A30,BS!$A$1:$A$36,BS!C$1:C$36,"",0,1)-1,"") | C30: =IFERROR(_xlfn.XLOOKUP($A30,BS!$A$1:$A$36,BS!C$1:C$36,"",0,1)/_xlfn.XLOOKUP($A30,BS!$A$1:$A$36,BS!D$1:D$36,"",0,1)-1,"") | D30: =IFERROR(_xlfn.XLOOKUP($A30,BS!$A$1:$A$36,BS!D$1:D$36,"",0,1)/_xlfn.XLOOKUP($A30,BS!$A$1:$A$36,BS!E$1:E$36,"",0,1)-1,"") | E30: =IFERROR(_xlfn.XLOOKUP($A30,BS!$A$1:$A$36,BS!E$1:E$36,"",0,1)/_xlfn.XLOOKUP($A30,BS!$A$1:$A$36,BS!F$1:F$36,"",0,1)-1,"")
A31: =BS!A31 | B31: =IFERROR(_xlfn.XLOOKUP($A31,BS!$A$1:$A$36,BS!B$1:B$36,"",0,1)/_xlfn.XLOOKUP($A31,BS!$A$1:$A$36,BS!C$1:C$36,"",0,1)-1,"") | C31: =IFERROR(_xlfn.XLOOKUP($A31,BS!$A$1:$A$36,BS!C$1:C$36,"",0,1)/_xlfn.XLOOKUP($A31,BS!$A$1:$A$36,BS!D$1:D$36,"",0,1)-1,"") | D31: =IFERROR(_xlfn.XLOOKUP($A31,BS!$A$1:$A$36,BS!D$1:D$36,"",0,1)/_xlfn.XLOOKUP($A31,BS!$A$1:$A$36,BS!E$1:E$36,"",0,1)-1,"") | E31: =IFERROR(_xlfn.XLOOKUP($A31,BS!$A$1:$A$36,BS!E$1:E$36,"",0,1)/_xlfn.XLOOKUP($A31,BS!$A$1:$A$36,BS!F$1:F$36,"",0,1)-1,"")
A32: =BS!A32 | B32: =IFERROR(_xlfn.XLOOKUP($A32,BS!$A$1:$A$36,BS!B$1:B$36,"",0,1)/_xlfn.XLOOKUP($A32,BS!$A$1:$A$36,BS!C$1:C$36,"",0,1)-1,"") | C32: =IFERROR(_xlfn.XLOOKUP($A32,BS!$A$1:$A$36,BS!C$1:C$36,"",0,1)/_xlfn.XLOOKUP($A32,BS!$A$1:$A$36,BS!D$1:D$36,"",0,1)-1,"") | D32: =IFERROR(_xlfn.XLOOKUP($A32,BS!$A$1:$A$36,BS!D$1:D$36,"",0,1)/_xlfn.XLOOKUP($A32,BS!$A$1:$A$36,BS!E$1:E$36,"",0,1)-1,"") | E32: =IFERROR(_xlfn.XLOOKUP($A32,BS!$A$1:$A$36,BS!E$1:E$36,"",0,1)/_xlfn.XLOOKUP($A32,BS!$A$1:$A$36,BS!F$1:F$36,"",0,1)-1,"")
A33: =BS!A33 | B33: =IFERROR(_xlfn.XLOOKUP($A33,BS!$A$1:$A$36,BS!B$1:B$36,"",0,1)/_xlfn.XLOOKUP($A33,BS!$A$1:$A$36,BS!C$1:C$36,"",0,1)-1,"") | C33: =IFERROR(_xlfn.XLOOKUP($A33,BS!$A$1:$A$36,BS!C$1:C$36,"",0,1)/_xlfn.XLOOKUP($A33,BS!$A$1:$A$36,BS!D$1:D$36,"",0,1)-1,"") | D33: =IFERROR(_xlfn.XLOOKUP($A33,BS!$A$1:$A$36,BS!D$1:D$36,"",0,1)/_xlfn.XLOOKUP($A33,BS!$A$1:$A$36,BS!E$1:E$36,"",0,1)-1,"") | E33: =IFERROR(_xlfn.XLOOKUP($A33,BS!$A$1:$A$36,BS!E$1:E$36,"",0,1)/_xlfn.XLOOKUP($A33,BS!$A$1:$A$36,BS!F$1:F$36,"",0,1)-1,"")
... A36: =BS!A36 | B36: =IFERROR(_xlfn.XLOOKUP($A36,BS!$A$1:$A$36,BS!B$1:B$36,"",0,1)/_xlfn.XLOOKUP($A36,BS!$A$1:$A$36,BS!C$1:C$36,"",0,1)-1,"") | C36: =IFERROR(_xlfn.XLOOKUP($A36,BS!$A$1:$A$36,BS!C$1:C$36,"",0,1)/_xlfn.XLOOKUP($A36,BS!$A$1:$A$36,BS!D$1:D$36,"",0,1)-1,"") | D36: =IFERROR(_xlfn.XLOOKUP($A36,BS!$A$1:$A$36,BS!D$1:D$36,"",0,1)/_xlfn.XLOOKUP($A36,BS!$A$1:$A$36,BS!E$1:E$36,"",0,1)-1,"") | E36: =IFERROR(_xlfn.XLOOKUP($A36,BS!$A$1:$A$36,BS!E$1:E$36,"",0,1)/_xlfn.XLOOKUP($A36,BS!$A$1:$A$36,BS!F$1:F$36,"",0,1)-1,"")

Sheet IS_COMM
A1: =IS!A1
A2: =IS!A2 | B2: =IS!B2 | C2: =IS!C2 | D2: =IS!D2 | E2: =IS!E2 | F2: =IS!F2
A3: =IS!A3
A4: =IS!A4 | B4: =_xlfn.XLOOKUP($A4,IS!$A$2:$A$28,IS!B$2:B$28," ",0,1)/_xlfn.XLOOKUP($A$6,IS!$A$2:$A$28,IS!B$2:B$28," ",0,1) | C4: =_xlfn.XLOOKUP($A4,IS!$A$2:$A$28,IS!C$2:C$28," ",0,1)/_xlfn.XLOOKUP($A$6,IS!$A$2:$A$28,IS!C$2:C$28," ",0,1) | D4: =_xlfn.XLOOKUP($A4,IS!$A$2:$A$28,IS!D$2:D$28," ",0,1)/_xlfn.XLOOKUP($A$6,IS!$A$2:$A$28,IS!D$2:D$28," ",0,1) | E4: =_xlfn.XLOOKUP($A4,IS!$A$2:$A$28,IS!E$2:E$28," ",0,1)/_xlfn.XLOOKUP($A$6,IS!$A$2:$A$28,IS!E$2:E$28," ",0,1) | F4: =_xlfn.XLOOKUP($A4,IS!$A$2:$A$28,IS!F$2:F$28," ",0,1)/_xlfn.XLOOKUP($A$6,IS!$A$2:$A$28,IS!F$2:F$28," ",0,1)
A5: =IS!A5 | B5: =_xlfn.XLOOKUP($A5,IS!$A$2:$A$28,IS!B$2:B$28," ",0,1)/_xlfn.XLOOKUP($A$6,IS!$A$2:$A$28,IS!B$2:B$28," ",0,1) | C5: =_xlfn.XLOOKUP($A5,IS!$A$2:$A$28,IS!C$2:C$28," ",0,1)/_xlfn.XLOOKUP($A$6,IS!$A$2:$A$28,IS!C$2:C$28," ",0,1) | D5: =_xlfn.XLOOKUP($A5,IS!$A$2:$A$28,IS!D$2:D$28," ",0,1)/_xlfn.XLOOKUP($A$6,IS!$A$2:$A$28,IS!D$2:D$28," ",0,1) | E5: =_xlfn.XLOOKUP($A5,IS!$A$2:$A$28,IS!E$2:E$28," ",0,1)/_xlfn.XLOOKUP($A$6,IS!$A$2:$A$28,IS!E$2:E$28," ",0,1) | F5: =_xlfn.XLOOKUP($A5,IS!$A$2:$A$28,IS!F$2:F$28," ",0,1)/_xlfn.XLOOKUP($A$6,IS!$A$2:$A$28,IS!F$2:F$28," ",0,1)
A6: =IS!A6 | B6: =_xlfn.XLOOKUP($A6,IS!$A$2:$A$28,IS!B$2:B$28," ",0,1)/_xlfn.XLOOKUP($A$6,IS!$A$2:$A$28,IS!B$2:B$28," ",0,1) | C6: =_xlfn.XLOOKUP($A6,IS!$A$2:$A$28,IS!C$2:C$28," ",0,1)/_xlfn.XLOOKUP($A$6,IS!$A$2:$A$28,IS!C$2:C$28," ",0,1) | D6: =_xlfn.XLOOKUP($A6,IS!$A$2:$A$28,IS!D$2:D$28," ",0,1)/_xlfn.XLOOKUP($A$6,IS!$A$2:$A$28,IS!D$2:D$28," ",0,1) | E6: =_xlfn.XLOOKUP($A6,IS!$A$2:$A$28,IS!E$2:E$28," ",0,1)/_xlfn.XLOOKUP($A$6,IS!$A$2:$A$28,IS!E$2:E$28," ",0,1) | F6: =_xlfn.XLOOKUP($A6,IS!$A$2:$A$28,IS!F$2:F$28," ",0,1)/_xlfn.XLOOKUP($A$6,IS!$A$2:$A$28,IS!F$2:F$28," ",0,1)
A7: =IS!A7 | B7: =_xlfn.XLOOKUP($A7,IS!$A$2:$A$28,IS!B$2:B$28," ",0,1)/_xlfn.XLOOKUP($A$6,IS!$A$2:$A$28,IS!B$2:B$28," ",0,1) | C7: =_xlfn.XLOOKUP($A7,IS!$A$2:$A$28,IS!C$2:C$28," ",0,1)/_xlfn.XLOOKUP($A$6,IS!$A$2:$A$28,IS!C$2:C$28," ",0,1) | D7: =_xlfn.XLOOKUP($A7,IS!$A$2:$A$28,IS!D$2:D$28," ",0,1)/_xlfn.XLOOKUP($A$6,IS!$A$2:$A$28,IS!D$2:D$28," ",0,1) | E7: =_xlfn.XLOOKUP($A7,IS!$A$2:$A$28,IS!E$2:E$28," ",0,1)/_xlfn.XLOOKUP($A$6,IS!$A$2:$A$28,IS!E$2:E$28," ",0,1) | F7: =_xlfn.XLOOKUP($A7,IS!$A$2:$A$28,IS!F$2:F$28," ",0,1)/_xlfn.XLOOKUP($A$6,IS!$A$2:$A$28,IS!F$2:F$28," ",0,1)
A8: =IS!A8 | B8: =_xlfn.XLOOKUP($A8,IS!$A$2:$A$28,IS!B$2:B$28," ",0,1)/_xlfn.XLOOKUP($A$6,IS!$A$2:$A$28,IS!B$2:B$28," ",0,1) | C8: =_xlfn.XLOOKUP($A8,IS!$A$2:$A$28,IS!C$2:C$28," ",0,1)/_xlfn.XLOOKUP($A$6,IS!$A$2:$A$28,IS!C$2:C$28," ",0,1) | D8: =_xlfn.XLOOKUP($A8,IS!$A$2:$A$28,IS!D$2:D$28," ",0,1)/_xlfn.XLOOKUP($A$6,IS!$A$2:$A$28,IS!D$2:D$28," ",0,1) | E8: =_xlfn.XLOOKUP($A8,IS!$A$2:$A$28,IS!E$2:E$28," ",0,1)/_xlfn.XLOOKUP($A$6,IS!$A$2:$A$28,IS!E$2:E$28," ",0,1) | F8: =_xlfn.XLOOKUP($A8,IS!$A$2:$A$28,IS!F$2:F$28," ",0,1)/_xlfn.XLOOKUP($A$6,IS!$A$2:$A$28,IS!F$2:F$28," ",0,1)
A9: =IS!A9 | B9: =_xlfn.XLOOKUP($A9,IS!$A$2:$A$28,IS!B$2:B$28," ",0,1)/_xlfn.XLOOKUP($A$6,IS!$A$2:$A$28,IS!B$2:B$28," ",0,1) | C9: =_xlfn.XLOOKUP($A9,IS!$A$2:$A$28,IS!C$2:C$28," ",0,1)/_xlfn.XLOOKUP($A$6,IS!$A$2:$A$28,IS!C$2:C$28," ",0,1) | D9: =_xlfn.XLOOKUP($A9,IS!$A$2:$A$28,IS!D$2:D$28," ",0,1)/_xlfn.XLOOKUP($A$6,IS!$A$2:$A$28,IS!D$2:D$28," ",0,1) | E9: =_xlfn.XLOOKUP($A9,IS!$A$2:$A$28,IS!E$2:E$28," ",0,1)/_xlfn.XLOOKUP($A$6,IS!$A$2:$A$28,IS!E$2:E$28," ",0,1) | F9: =_xlfn.XLOOKUP($A9,IS!$A$2:$A$28,IS!F$2:F$28," ",0,1)/_xlfn.XLOOKUP($A$6,IS!$A$2:$A$28,IS!F$2:F$28," ",0,1)
A10: =IS!A10 | B10: =_xlfn.XLOOKUP($A10,IS!$A$2:$A$28,IS!B$2:B$28," ",0,1)/_xlfn.XLOOKUP($A$6,IS!$A$2:$A$28,IS!B$2:B$28," ",0,1) | C10: =_xlfn.XLOOKUP($A10,IS!$A$2:$A$28,IS!C$2:C$28," ",0,1)/_xlfn.XLOOKUP($A$6,IS!$A$2:$A$28,IS!C$2:C$28," ",0,1) | D10: =_xlfn.XLOOKUP($A10,IS!$A$2:$A$28,IS!D$2:D$28," ",0,1)/_xlfn.XLOOKUP($A$6,IS!$A$2:$A$28,IS!D$2:D$28," ",0,1) | E10: =_xlfn.XLOOKUP($A10,IS!$A$2:$A$28,IS!E$2:E$28," ",0,1)/_xlfn.XLOOKUP($A$6,IS!$A$2:$A$28,IS!E$2:E$28," ",0,1) | F10: =_xlfn.XLOOKUP($A10,IS!$A$2:$A$28,IS!F$2:F$28," ",0,1)/_xlfn.XLOOKUP($A$6,IS!$A$2:$A$28,IS!F$2:F$28," ",0,1)
A11: =IS!A11 | B11: =_xlfn.XLOOKUP($A11,IS!$A$2:$A$28,IS!B$2:B$28," ",0,1)/_xlfn.XLOOKUP($A$6,IS!$A$2:$A$28,IS!B$2:B$28," ",0,1) | C11: =_xlfn.XLOOKUP($A11,IS!$A$2:$A$28,IS!C$2:C$28," ",0,1)/_xlfn.XLOOKUP($A$6,IS!$A$2:$A$28,IS!C$2:C$28," ",0,1) | D11: =_xlfn.XLOOKUP($A11,IS!$A$2:$A$28,IS!D$2:D$28," ",0,1)/_xlfn.XLOOKUP($A$6,IS!$A$2:$A$28,IS!D$2:D$28," ",0,1) | E11: =_xlfn.XLOOKUP($A11,IS!$A$2:$A$28,IS!E$2:E$28," ",0,1)/_xlfn.XLOOKUP($A$6,IS!$A$2:$A$28,IS!E$2:E$28," ",0,1) | F11: =_xlfn.XLOOKUP($A11,IS!$A$2:$A$28,IS!F$2:F$28," ",0,1)/_xlfn.XLOOKUP($A$6,IS!$A$2:$A$28,IS!F$2:F$28," ",0,1)
A12: =IS!A12 | B12: =_xlfn.XLOOKUP($A12,IS!$A$2:$A$28,IS!B$2:B$28," ",0,1)/_xlfn.XLOOKUP($A$6,IS!$A$2:$A$28,IS!B$2:B$28," ",0,1) | C12: =_xlfn.XLOOKUP($A12,IS!$A$2:$A$28,IS!C$2:C$28," ",0,1)/_xlfn.XLOOKUP($A$6,IS!$A$2:$A$28,IS!C$2:C$28," ",0,1) | D12: =_xlfn.XLOOKUP($A12,IS!$A$2:$A$28,IS!D$2:D$28," ",0,1)/_xlfn.XLOOKUP($A$6,IS!$A$2:$A$28,IS!D$2:D$28," ",0,1) | E12: =_xlfn.XLOOKUP($A12,IS!$A$2:$A$28,IS!E$2:E$28," ",0,1)/_xlfn.XLOOKUP($A$6,IS!$A$2:$A$28,IS!E$2:E$28," ",0,1) | F12: =_xlfn.XLOOKUP($A12,IS!$A$2:$A$28,IS!F$2:F$28," ",0,1)/_xlfn.XLOOKUP($A$6,IS!$A$2:$A$28,IS!F$2:F$28," ",0,1)
A13: =IS!A13 | B13: =_xlfn.XLOOKUP($A13,IS!$A$2:$A$28,IS!B$2:B$28," ",0,1)/_xlfn.XLOOKUP($A$6,IS!$A$2:$A$28,IS!B$2:B$28," ",0,1) | C13: =_xlfn.XLOOKUP($A13,IS!$A$2:$A$28,IS!C$2:C$28," ",0,1)/_xlfn.XLOOKUP($A$6,IS!$A$2:$A$28,IS!C$2:C$28," ",0,1) | D13: =_xlfn.XLOOKUP($A13,IS!$A$2:$A$28,IS!D$2:D$28," ",0,1)/_xlfn.XLOOKUP($A$6,IS!$A$2:$A$28,IS!D$2:D$28," ",0,1) | E13: =_xlfn.XLOOKUP($A13,IS!$A$2:$A$28,IS!E$2:E$28," ",0,1)/_xlfn.XLOOKUP($A$6,IS!$A$2:$A$28,IS!E$2:E$28," ",0,1) | F13: =_xlfn.XLOOKUP($A13,IS!$A$2:$A$28,IS!F$2:F$28," ",0,1)/_xlfn.XLOOKUP($A$6,IS!$A$2:$A$28,IS!F$2:F$28," ",0,1)
A14: =IS!A14 | B14: =_xlfn.XLOOKUP($A14,IS!$A$2:$A$28,IS!B$2:B$28," ",0,1)/_xlfn.XLOOKUP($A$6,IS!$A$2:$A$28,IS!B$2:B$28," ",0,1) | C14: =_xlfn.XLOOKUP($A14,IS!$A$2:$A$28,IS!C$2:C$28," ",0,1)/_xlfn.XLOOKUP($A$6,IS!$A$2:$A$28,IS!C$2:C$28," ",0,1) | D14: =_xlfn.XLOOKUP($A14,IS!$A$2:$A$28,IS!D$2:D$28," ",0,1)/_xlfn.XLOOKUP($A$6,IS!$A$2:$A$28,IS!D$2:D$28," ",0,1) | E14: =_xlfn.XLOOKUP($A14,IS!$A$2:$A$28,IS!E$2:E$28," ",0,1)/_xlfn.XLOOKUP($A$6,IS!$A$2:$A$28,IS!E$2:E$28," ",0,1) | F14: =_xlfn.XLOOKUP($A14,IS!$A$2:$A$28,IS!F$2:F$28," ",0,1)/_xlfn.XLOOKUP($A$6,IS!$A$2:$A$28,IS!F$2:F$28," ",0,1)
A15: =IS!A15 | B15: =_xlfn.XLOOKUP($A15,IS!$A$2:$A$28,IS!B$2:B$28," ",0,1)/_xlfn.XLOOKUP($A$6,IS!$A$2:$A$28,IS!B$2:B$28," ",0,1) | C15: =_xlfn.XLOOKUP($A15,IS!$A$2:$A$28,IS!C$2:C$28," ",0,1)/_xlfn.XLOOKUP($A$6,IS!$A$2:$A$28,IS!C$2:C$28," ",0,1) | D15: =_xlfn.XLOOKUP($A15,IS!$A$2:$A$28,IS!D$2:D$28," ",0,1)/_xlfn.XLOOKUP($A$6,IS!$A$2:$A$28,IS!D$2:D$28," ",0,1) | E15: =_xlfn.XLOOKUP($A15,IS!$A$2:$A$28,IS!E$2:E$28," ",0,1)/_xlfn.XLOOKUP($A$6,IS!$A$2:$A$28,IS!E$2:E$28," ",0,1) | F15: =_xlfn.XLOOKUP($A15,IS!$A$2:$A$28,IS!F$2:F$28," ",0,1)/_xlfn.XLOOKUP($A$6,IS!$A$2:$A$28,IS!F$2:F$28," ",0,1)
... A27: =IS!A27 | B27: =_xlfn.XLOOKUP($A27,IS!$A$2:$A$28,IS!B$2:B$28," ",0,1)/_xlfn.XLOOKUP($A$6,IS!$A$2:$A$28,IS!B$2:B$28," ",0,1) | C27: =_xlfn.XLOOKUP($A27,IS!$A$2:$A$28,IS!C$2:C$28," ",0,1)/_xlfn.XLOOKUP($A$6,IS!$A$2:$A$28,IS!C$2:C$28," ",0,1) | D27: =_xlfn.XLOOKUP($A27,IS!$A$2:$A$28,IS!D$2:D$28," ",0,1)/_xlfn.XLOOKUP($A$6,IS!$A$2:$A$28,IS!D$2:D$28," ",0,1) | E27: =_xlfn.XLOOKUP($A27,IS!$A$2:$A$28,IS!E$2:E$28," ",0,1)/_xlfn.XLOOKUP($A$6,IS!$A$2:$A$28,IS!E$2:E$28," ",0,1) | F27: =_xlfn.XLOOKUP($A27,IS!$A$2:$A$28,IS!F$2:F$28," ",0,1)/_xlfn.XLOOKUP($A$6,IS!$A$2:$A$28,IS!F$2:F$28," ",0,1)

Sheet BS_COMM
A1: =BS!A1
A2: =BS!A2 | B2: =BS!B2 | C2: =BS!C2 | D2: =BS!D2 | E2: =BS!E2 | F2: =BS!F2
A3: =BS!A3
A4: =BS!A4 | B4: =_xlfn.XLOOKUP($A4,BS!$A$1:$A$36,BS!B$1:B$36,,0,1)/_xlfn.XLOOKUP($A$20,BS!$A$1:$A$36,BS!B$1:B$36,,0,1) | C4: =_xlfn.XLOOKUP($A4,BS!$A$1:$A$36,BS!C$1:C$36,,0,1)/_xlfn.XLOOKUP($A$20,BS!$A$1:$A$36,BS!C$1:C$36,,0,1) | D4: =_xlfn.XLOOKUP($A4,BS!$A$1:$A$36,BS!D$1:D$36,,0,1)/_xlfn.XLOOKUP($A$20,BS!$A$1:$A$36,BS!D$1:D$36,,0,1) | E4: =_xlfn.XLOOKUP($A4,BS!$A$1:$A$36,BS!E$1:E$36,,0,1)/_xlfn.XLOOKUP($A$20,BS!$A$1:$A$36,BS!E$1:E$36,,0,1) | F4: =_xlfn.XLOOKUP($A4,BS!$A$1:$A$36,BS!F$1:F$36,,0,1)/_xlfn.XLOOKUP($A$20,BS!$A$1:$A$36,BS!F$1:F$36,,0,1)
A5: =BS!A5 | B5: =_xlfn.XLOOKUP($A5,BS!$A$1:$A$36,BS!B$1:B$36,,0,1)/_xlfn.XLOOKUP($A$20,BS!$A$1:$A$36,BS!B$1:B$36,,0,1) | C5: =_xlfn.XLOOKUP($A5,BS!$A$1:$A$36,BS!C$1:C$36,,0,1)/_xlfn.XLOOKUP($A$20,BS!$A$1:$A$36,BS!C$1:C$36,,0,1) | D5: =_xlfn.XLOOKUP($A5,BS!$A$1:$A$36,BS!D$1:D$36,,0,1)/_xlfn.XLOOKUP($A$20,BS!$A$1:$A$36,BS!D$1:D$36,,0,1) | E5: =_xlfn.XLOOKUP($A5,BS!$A$1:$A$36,BS!E$1:E$36,,0,1)/_xlfn.XLOOKUP($A$20,BS!$A$1:$A$36,BS!E$1:E$36,,0,1) | F5: =_xlfn.XLOOKUP($A5,BS!$A$1:$A$36,BS!F$1:F$36,,0,1)/_xlfn.XLOOKUP($A$20,BS!$A$1:$A$36,BS!F$1:F$36,,0,1)
A6: =BS!A6 | B6: =_xlfn.XLOOKUP($A6,BS!$A$1:$A$36,BS!B$1:B$36,,0,1)/_xlfn.XLOOKUP($A$20,BS!$A$1:$A$36,BS!B$1:B$36,,0,1) | C6: =_xlfn.XLOOKUP($A6,BS!$A$1:$A$36,BS!C$1:C$36,,0,1)/_xlfn.XLOOKUP($A$20,BS!$A$1:$A$36,BS!C$1:C$36,,0,1) | D6: =_xlfn.XLOOKUP($A6,BS!$A$1:$A$36,BS!D$1:D$36,,0,1)/_xlfn.XLOOKUP($A$20,BS!$A$1:$A$36,BS!D$1:D$36,,0,1) | E6: =_xlfn.XLOOKUP($A6,BS!$A$1:$A$36,BS!E$1:E$36,,0,1)/_xlfn.XLOOKUP($A$20,BS!$A$1:$A$36,BS!E$1:E$36,,0,1) | F6: =_xlfn.XLOOKUP($A6,BS!$A$1:$A$36,BS!F$1:F$36,,0,1)/_xlfn.XLOOKUP($A$20,BS!$A$1:$A$36,BS!F$1:F$36,,0,1)
A7: =BS!A7 | B7: =_xlfn.XLOOKUP($A7,BS!$A$1:$A$36,BS!B$1:B$36,,0,1)/_xlfn.XLOOKUP($A$20,BS!$A$1:$A$36,BS!B$1:B$36,,0,1) | C7: =_xlfn.XLOOKUP($A7,BS!$A$1:$A$36,BS!C$1:C$36,,0,1)/_xlfn.XLOOKUP($A$20,BS!$A$1:$A$36,BS!C$1:C$36,,0,1) | D7: =_xlfn.XLOOKUP($A7,BS!$A$1:$A$36,BS!D$1:D$36,,0,1)/_xlfn.XLOOKUP($A$20,BS!$A$1:$A$36,BS!D$1:D$36,,0,1) | E7: =_xlfn.XLOOKUP($A7,BS!$A$1:$A$36,BS!E$1:E$36,,0,1)/_xlfn.XLOOKUP($A$20,BS!$A$1:$A$36,BS!E$1:E$36,,0,1) | F7: =_xlfn.XLOOKUP($A7,BS!$A$1:$A$36,BS!F$1:F$36,,0,1)/_xlfn.XLOOKUP($A$20,BS!$A$1:$A$36,BS!F$1:F$36,,0,1)
A8: =BS!A8 | B8: =_xlfn.XLOOKUP($A8,BS!$A$1:$A$36,BS!B$1:B$36,,0,1)/_xlfn.XLOOKUP($A$20,BS!$A$1:$A$36,BS!B$1:B$36,,0,1) | C8: =_xlfn.XLOOKUP($A8,BS!$A$1:$A$36,BS!C$1:C$36,,0,1)/_xlfn.XLOOKUP($A$20,BS!$A$1:$A$36,BS!C$1:C$36,,0,1) | D8: =_xlfn.XLOOKUP($A8,BS!$A$1:$A$36,BS!D$1:D$36,,0,1)/_xlfn.XLOOKUP($A$20,BS!$A$1:$A$36,BS!D$1:D$36,,0,1) | E8: =_xlfn.XLOOKUP($A8,BS!$A$1:$A$36,BS!E$1:E$36,,0,1)/_xlfn.XLOOKUP($A$20,BS!$A$1:$A$36,BS!E$1:E$36,,0,1) | F8: =_xlfn.XLOOKUP($A8,BS!$A$1:$A$36,BS!F$1:F$36,,0,1)/_xlfn.XLOOKUP($A$20,BS!$A$1:$A$36,BS!F$1:F$36,,0,1)
A9: =BS!A9 | B9: =_xlfn.XLOOKUP($A9,BS!$A$1:$A$36,BS!B$1:B$36,,0,1)/_xlfn.XLOOKUP($A$20,BS!$A$1:$A$36,BS!B$1:B$36,,0,1) | C9: =_xlfn.XLOOKUP($A9,BS!$A$1:$A$36,BS!C$1:C$36,,0,1)/_xlfn.XLOOKUP($A$20,BS!$A$1:$A$36,BS!C$1:C$36,,0,1) | D9: =_xlfn.XLOOKUP($A9,BS!$A$1:$A$36,BS!D$1:D$36,,0,1)/_xlfn.XLOOKUP($A$20,BS!$A$1:$A$36,BS!D$1:D$36,,0,1) | E9: =_xlfn.XLOOKUP($A9,BS!$A$1:$A$36,BS!E$1:E$36,,0,1)/_xlfn.XLOOKUP($A$20,BS!$A$1:$A$36,BS!E$1:E$36,,0,1) | F9: =_xlfn.XLOOKUP($A9,BS!$A$1:$A$36,BS!F$1:F$36,,0,1)/_xlfn.XLOOKUP($A$20,BS!$A$1:$A$36,BS!F$1:F$36,,0,1)
A10: =BS!A10 | B10: =_xlfn.XLOOKUP($A10,BS!$A$1:$A$36,BS!B$1:B$36,,0,1)/_xlfn.XLOOKUP($A$20,BS!$A$1:$A$36,BS!B$1:B$36,,0,1) | C10: =_xlfn.XLOOKUP($A10,BS!$A$1:$A$36,BS!C$1:C$36,,0,1)/_xlfn.XLOOKUP($A$20,BS!$A$1:$A$36,BS!C$1:C$36,,0,1) | D10: =_xlfn.XLOOKUP($A10,BS!$A$1:$A$36,BS!D$1:D$36,,0,1)/_xlfn.XLOOKUP($A$20,BS!$A$1:$A$36,BS!D$1:D$36,,0,1) | E10: =_xlfn.XLOOKUP($A10,BS!$A$1:$A$36,BS!E$1:E$36,,0,1)/_xlfn.XLOOKUP($A$20,BS!$A$1:$A$36,BS!E$1:E$36,,0,1) | F10: =_xlfn.XLOOKUP($A10,BS!$A$1:$A$36,BS!F$1:F$36,,0,1)/_xlfn.XLOOKUP($A$20,BS!$A$1:$A$36,BS!F$1:F$36,,0,1)
A11: =BS!A11 | B11: =_xlfn.XLOOKUP($A11,BS!$A$1:$A$36,BS!B$1:B$36,,0,1)/_xlfn.XLOOKUP($A$20,BS!$A$1:$A$36,BS!B$1:B$36,,0,1) | C11: =_xlfn.XLOOKUP($A11,BS!$A$1:$A$36,BS!C$1:C$36,,0,1)/_xlfn.XLOOKUP($A$20,BS!$A$1:$A$36,BS!C$1:C$36,,0,1) | D11: =_xlfn.XLOOKUP($A11,BS!$A$1:$A$36,BS!D$1:D$36,,0,1)/_xlfn.XLOOKUP($A$20,BS!$A$1:$A$36,BS!D$1:D$36,,0,1) | E11: =_xlfn.XLOOKUP($A11,BS!$A$1:$A$36,BS!E$1:E$36,,0,1)/_xlfn.XLOOKUP($A$20,BS!$A$1:$A$36,BS!E$1:E$36,,0,1) | F11: =_xlfn.XLOOKUP($A11,BS!$A$1:$A$36,BS!F$1:F$36,,0,1)/_xlfn.XLOOKUP($A$20,BS!$A$1:$A$36,BS!F$1:F$36,,0,1)
A12: =BS!A12 | B12: =_xlfn.XLOOKUP($A12,BS!$A$1:$A$36,BS!B$1:B$36,,0,1)/_xlfn.XLOOKUP($A$20,BS!$A$1:$A$36,BS!B$1:B$36,,0,1) | C12: =_xlfn.XLOOKUP($A12,BS!$A$1:$A$36,BS!C$1:C$36,,0,1)/_xlfn.XLOOKUP($A$20,BS!$A$1:$A$36,BS!C$1:C$36,,0,1) | D12: =_xlfn.XLOOKUP($A12,BS!$A$1:$A$36,BS!D$1:D$36,,0,1)/_xlfn.XLOOKUP($A$20,BS!$A$1:$A$36,BS!D$1:D$36,,0,1) | E12: =_xlfn.XLOOKUP($A12,BS!$A$1:$A$36,BS!E$1:E$36,,0,1)/_xlfn.XLOOKUP($A$20,BS!$A$1:$A$36,BS!E$1:E$36,,0,1) | F12: =_xlfn.XLOOKUP($A12,BS!$A$1:$A$36,BS!F$1:F$36,,0,1)/_xlfn.XLOOKUP($A$20,BS!$A$1:$A$36,BS!F$1:F$36,,0,1)
A13: =BS!A13 | B13: =_xlfn.XLOOKUP($A13,BS!$A$1:$A$36,BS!B$1:B$36,,0,1)/_xlfn.XLOOKUP($A$20,BS!$A$1:$A$36,BS!B$1:B$36,,0,1) | C13: =_xlfn.XLOOKUP($A13,BS!$A$1:$A$36,BS!C$1:C$36,,0,1)/_xlfn.XLOOKUP($A$20,BS!$A$1:$A$36,BS!C$1:C$36,,0,1) | D13: =_xlfn.XLOOKUP($A13,BS!$A$1:$A$36,BS!D$1:D$36,,0,1)/_xlfn.XLOOKUP($A$20,BS!$A$1:$A$36,BS!D$1:D$36,,0,1) | E13: =_xlfn.XLOOKUP($A13,BS!$A$1:$A$36,BS!E$1:E$36,,0,1)/_xlfn.XLOOKUP($A$20,BS!$A$1:$A$36,BS!E$1:E$36,,0,1) | F13: =_xlfn.XLOOKUP($A13,BS!$A$1:$A$36,BS!F$1:F$36,,0,1)/_xlfn.XLOOKUP($A$20,BS!$A$1:$A$36,BS!F$1:F$36,,0,1)
A14: =BS!A14 | B14: =_xlfn.XLOOKUP($A14,BS!$A$1:$A$36,BS!B$1:B$36,,0,1)/_xlfn.XLOOKUP($A$20,BS!$A$1:$A$36,BS!B$1:B$36,,0,1) | C14: =_xlfn.XLOOKUP($A14,BS!$A$1:$A$36,BS!C$1:C$36,,0,1)/_xlfn.XLOOKUP($A$20,BS!$A$1:$A$36,BS!C$1:C$36,,0,1) | D14: =_xlfn.XLOOKUP($A14,BS!$A$1:$A$36,BS!D$1:D$36,,0,1)/_xlfn.XLOOKUP($A$20,BS!$A$1:$A$36,BS!D$1:D$36,,0,1) | E14: =_xlfn.XLOOKUP($A14,BS!$A$1:$A$36,BS!E$1:E$36,,0,1)/_xlfn.XLOOKUP($A$20,BS!$A$1:$A$36,BS!E$1:E$36,,0,1) | F14: =_xlfn.XLOOKUP($A14,BS!$A$1:$A$36,BS!F$1:F$36,,0,1)/_xlfn.XLOOKUP($A$20,BS!$A$1:$A$36,BS!F$1:F$36,,0,1)
A15: =BS!A15 | B15: =_xlfn.XLOOKUP($A15,BS!$A$1:$A$36,BS!B$1:B$36,,0,1)/_xlfn.XLOOKUP($A$20,BS!$A$1:$A$36,BS!B$1:B$36,,0,1) | C15: =_xlfn.XLOOKUP($A15,BS!$A$1:$A$36,BS!C$1:C$36,,0,1)/_xlfn.XLOOKUP($A$20,BS!$A$1:$A$36,BS!C$1:C$36,,0,1) | D15: =_xlfn.XLOOKUP($A15,BS!$A$1:$A$36,BS!D$1:D$36,,0,1)/_xlfn.XLOOKUP($A$20,BS!$A$1:$A$36,BS!D$1:D$36,,0,1) | E15: =_xlfn.XLOOKUP($A15,BS!$A$1:$A$36,BS!E$1:E$36,,0,1)/_xlfn.XLOOKUP($A$20,BS!$A$1:$A$36,BS!E$1:E$36,,0,1) | F15: =_xlfn.XLOOKUP($A15,BS!$A$1:$A$36,BS!F$1:F$36,,0,1)/_xlfn.XLOOKUP($A$20,BS!$A$1:$A$36,BS!F$1:F$36,,0,1)
... A20: =BS!A20 | B20: =_xlfn.XLOOKUP($A20,BS!$A$1:$A$36,BS!B$1:B$36,,0,1)/_xlfn.XLOOKUP($A$20,BS!$A$1:$A$36,BS!B$1:B$36,,0,1) | C20: =_xlfn.XLOOKUP($A20,BS!$A$1:$A$36,BS!C$1:C$36,,0,1)/_xlfn.XLOOKUP($A$20,BS!$A$1:$A$36,BS!C$1:C$36,,0,1) | D20: =_xlfn.XLOOKUP($A20,BS!$A$1:$A$36,BS!D$1:D$36,,0,1)/_xlfn.XLOOKUP($A$20,BS!$A$1:$A$36,BS!D$1:D$36,,0,1) | E20: =_xlfn.XLOOKUP($A20,BS!$A$1:$A$36,BS!E$1:E$36,,0,1)/_xlfn.XLOOKUP($A$20,BS!$A$1:$A$36,BS!E$1:E$36,,0,1) | F20: =_xlfn.XLOOKUP($A20,BS!$A$1:$A$36,BS!F$1:F$36,,0,1)/_xlfn.XLOOKUP($A$20,BS!$A$1:$A$36,BS!F$1:F$36,,0,1)
A22: =BS!A22
A23: =BS!A23 | B23: =_xlfn.XLOOKUP($A23,BS!$A$1:$A$36,BS!B$1:B$36,,0,1)/_xlfn.XLOOKUP($A$20,BS!$A$1:$A$36,BS!B$1:B$36,,0,1) | C23: =_xlfn.XLOOKUP($A23,BS!$A$1:$A$36,BS!C$1:C$36,,0,1)/_xlfn.XLOOKUP($A$20,BS!$A$1:$A$36,BS!C$1:C$36,,0,1) | D23: =_xlfn.XLOOKUP($A23,BS!$A$1:$A$36,BS!D$1:D$36,,0,1)/_xlfn.XLOOKUP($A$20,BS!$A$1:$A$36,BS!D$1:D$36,,0,1) | E23: =_xlfn.XLOOKUP($A23,BS!$A$1:$A$36,BS!E$1:E$36,,0,1)/_xlfn.XLOOKUP($A$20,BS!$A$1:$A$36,BS!E$1:E$36,,0,1) | F23: =_xlfn.XLOOKUP($A23,BS!$A$1:$A$36,BS!F$1:F$36,,0,1)/_xlfn.XLOOKUP($A$20,BS!$A$1:$A$36,BS!F$1:F$36,,0,1)
A24: =BS!A24 | B24: =_xlfn.XLOOKUP($A24,BS!$A$1:$A$36,BS!B$1:B$36,,0,1)/_xlfn.XLOOKUP($A$20,BS!$A$1:$A$36,BS!B$1:B$36,,0,1) | C24: =_xlfn.XLOOKUP($A24,BS!$A$1:$A$36,BS!C$1:C$36,,0,1)/_xlfn.XLOOKUP($A$20,BS!$A$1:$A$36,BS!C$1:C$36,,0,1) | D24: =_xlfn.XLOOKUP($A24,BS!$A$1:$A$36,BS!D$1:D$36,,0,1)/_xlfn.XLOOKUP($A$20,BS!$A$1:$A$36,BS!D$1:D$36,,0,1) | E24: =_xlfn.XLOOKUP($A24,BS!$A$1:$A$36,BS!E$1:E$36,,0,1)/_xlfn.XLOOKUP($A$20,BS!$A$1:$A$36,BS!E$1:E$36,,0,1) | F24: =_xlfn.XLOOKUP($A24,BS!$A$1:$A$36,BS!F$1:F$36,,0,1)/_xlfn.XLOOKUP($A$20,BS!$A$1:$A$36,BS!F$1:F$36,,0,1)
A25: =BS!A25 | B25: =_xlfn.XLOOKUP($A25,BS!$A$1:$A$36,BS!B$1:B$36,,0,1)/_xlfn.XLOOKUP($A$20,BS!$A$1:$A$36,BS!B$1:B$36,,0,1) | C25: =_xlfn.XLOOKUP($A25,BS!$A$1:$A$36,BS!C$1:C$36,,0,1)/_xlfn.XLOOKUP($A$20,BS!$A$1:$A$36,BS!C$1:C$36,,0,1) | D25: =_xlfn.XLOOKUP($A25,BS!$A$1:$A$36,BS!D$1:D$36,,0,1)/_xlfn.XLOOKUP($A$20,BS!$A$1:$A$36,BS!D$1:D$36,,0,1) | E25: =_xlfn.XLOOKUP($A25,BS!$A$1:$A$36,BS!E$1:E$36,,0,1)/_xlfn.XLOOKUP($A$20,BS!$A$1:$A$36,BS!E$1:E$36,,0,1) | F25: =_xlfn.XLOOKUP($A25,BS!$A$1:$A$36,BS!F$1:F$36,,0,1)/_xlfn.XLOOKUP($A$20,BS!$A$1:$A$36,BS!F$1:F$36,,0,1)
A26: =BS!A26 | B26: =_xlfn.XLOOKUP($A26,BS!$A$1:$A$36,BS!B$1:B$36,,0,1)/_xlfn.XLOOKUP($A$20,BS!$A$1:$A$36,BS!B$1:B$36,,0,1) | C26: =_xlfn.XLOOKUP($A26,BS!$A$1:$A$36,BS!C$1:C$36,,0,1)/_xlfn.XLOOKUP($A$20,BS!$A$1:$A$36,BS!C$1:C$36,,0,1) | D26: =_xlfn.XLOOKUP($A26,BS!$A$1:$A$36,BS!D$1:D$36,,0,1)/_xlfn.XLOOKUP($A$20,BS!$A$1:$A$36,BS!D$1:D$36,,0,1) | E26: =_xlfn.XLOOKUP($A26,BS!$A$1:$A$36,BS!E$1:E$36,,0,1)/_xlfn.XLOOKUP($A$20,BS!$A$1:$A$36,BS!E$1:E$36,,0,1) | F26: =_xlfn.XLOOKUP($A26,BS!$A$1:$A$36,BS!F$1:F$36,,0,1)/_xlfn.XLOOKUP($A$20,BS!$A$1:$A$36,BS!F$1:F$36,,0,1)
A27: =BS!A27 | B27: =_xlfn.XLOOKUP($A27,BS!$A$1:$A$36,BS!B$1:B$36,,0,1)/_xlfn.XLOOKUP($A$20,BS!$A$1:$A$36,BS!B$1:B$36,,0,1) | C27: =_xlfn.XLOOKUP($A27,BS!$A$1:$A$36,BS!C$1:C$36,,0,1)/_xlfn.XLOOKUP($A$20,BS!$A$1:$A$36,BS!C$1:C$36,,0,1) | D27: =_xlfn.XLOOKUP($A27,BS!$A$1:$A$36,BS!D$1:D$36,,0,1)/_xlfn.XLOOKUP($A$20,BS!$A$1:$A$36,BS!D$1:D$36,,0,1) | E27: =_xlfn.XLOOKUP($A27,BS!$A$1:$A$36,BS!E$1:E$36,,0,1)/_xlfn.XLOOKUP($A$20,BS!$A$1:$A$36,BS!E$1:E$36,,0,1) | F27: =_xlfn.XLOOKUP($A27,BS!$A$1:$A$36,BS!F$1:F$36,,0,1)/_xlfn.XLOOKUP($A$20,BS!$A$1:$A$36,BS!F$1:F$36,,0,1)
A28: =BS!A28 | B28: =_xlfn.XLOOKUP($A28,BS!$A$1:$A$36,BS!B$1:B$36,,0,1)/_xlfn.XLOOKUP($A$20,BS!$A$1:$A$36,BS!B$1:B$36,,0,1) | C28: =_xlfn.XLOOKUP($A28,BS!$A$1:$A$36,BS!C$1:C$36,,0,1)/_xlfn.XLOOKUP($A$20,BS!$A$1:$A$36,BS!C$1:C$36,,0,1) | D28: =_xlfn.XLOOKUP($A28,BS!$A$1:$A$36,BS!D$1:D$36,,0,1)/_xlfn.XLOOKUP($A$20,BS!$A$1:$A$36,BS!D$1:D$36,,0,1) | E28: =_xlfn.XLOOKUP($A28,BS!$A$1:$A$36,BS!E$1:E$36,,0,1)/_xlfn.XLOOKUP($A$20,BS!$A$1:$A$36,BS!E$1:E$36,,0,1) | F28: =_xlfn.XLOOKUP($A28,BS!$A$1:$A$36,BS!F$1:F$36,,0,1)/_xlfn.XLOOKUP($A$20,BS!$A$1:$A$36,BS!F$1:F$36,,0,1)
A29: =BS!A29 | B29: =_xlfn.XLOOKUP($A29,BS!$A$1:$A$36,BS!B$1:B$36,,0,1)/_xlfn.XLOOKUP($A$20,BS!$A$1:$A$36,BS!B$1:B$36,,0,1) | C29: =_xlfn.XLOOKUP($A29,BS!$A$1:$A$36,BS!C$1:C$36,,0,1)/_xlfn.XLOOKUP($A$20,BS!$A$1:$A$36,BS!C$1:C$36,,0,1) | D29: =_xlfn.XLOOKUP($A29,BS!$A$1:$A$36,BS!D$1:D$36,,0,1)/_xlfn.XLOOKUP($A$20,BS!$A$1:$A$36,BS!D$1:D$36,,0,1) | E29: =_xlfn.XLOOKUP($A29,BS!$A$1:$A$36,BS!E$1:E$36,,0,1)/_xlfn.XLOOKUP($A$20,BS!$A$1:$A$36,BS!E$1:E$36,,0,1) | F29: =_xlfn.XLOOKUP($A29,BS!$A$1:$A$36,BS!F$1:F$36,,0,1)/_xlfn.XLOOKUP($A$20,BS!$A$1:$A$36,BS!F$1:F$36,,0,1)
A30: =BS!A30 | B30: =_xlfn.XLOOKUP($A30,BS!$A$1:$A$36,BS!B$1:B$36,,0,1)/_xlfn.XLOOKUP($A$20,BS!$A$1:$A$36,BS!B$1:B$36,,0,1) | C30: =_xlfn.XLOOKUP($A30,BS!$A$1:$A$36,BS!C$1:C$36,,0,1)/_xlfn.XLOOKUP($A$20,BS!$A$1:$A$36,BS!C$1:C$36,,0,1) | D30: =_xlfn.XLOOKUP($A30,BS!$A$1:$A$36,BS!D$1:D$36,,0,1)/_xlfn.XLOOKUP($A$20,BS!$A$1:$A$36,BS!D$1:D$36,,0,1) | E30: =_xlfn.XLOOKUP($A30,BS!$A$1:$A$36,BS!E$1:E$36,,0,1)/_xlfn.XLOOKUP($A$20,BS!$A$1:$A$36,BS!E$1:E$36,,0,1) | F30: =_xlfn.XLOOKUP($A30,BS!$A$1:$A$36,BS!F$1:F$36,,0,1)/_xlfn.XLOOKUP($A$20,BS!$A$1:$A$36,BS!F$1:F$36,,0,1)
A31: =BS!A31 | B31: =_xlfn.XLOOKUP($A31,BS!$A$1:$A$36,BS!B$1:B$36,,0,1)/_xlfn.XLOOKUP($A$20,BS!$A$1:$A$36,BS!B$1:B$36,,0,1) | C31: =_xlfn.XLOOKUP($A31,BS!$A$1:$A$36,BS!C$1:C$36,,0,1)/_xlfn.XLOOKUP($A$20,BS!$A$1:$A$36,BS!C$1:C$36,,0,1) | D31: =_xlfn.XLOOKUP($A31,BS!$A$1:$A$36,BS!D$1:D$36,,0,1)/_xlfn.XLOOKUP($A$20,BS!$A$1:$A$36,BS!D$1:D$36,,0,1) | E31: =_xlfn.XLOOKUP($A31,BS!$A$1:$A$36,BS!E$1:E$36,,0,1)/_xlfn.XLOOKUP($A$20,BS!$A$1:$A$36,BS!E$1:E$36,,0,1) | F31: =_xlfn.XLOOKUP($A31,BS!$A$1:$A$36,BS!F$1:F$36,,0,1)/_xlfn.XLOOKUP($A$20,BS!$A$1:$A$36,BS!F$1:F$36,,0,1)
A32: =BS!A32 | B32: =_xlfn.XLOOKUP($A32,BS!$A$1:$A$36,BS!B$1:B$36,,0,1)/_xlfn.XLOOKUP($A$20,BS!$A$1:$A$36,BS!B$1:B$36,,0,1) | C32: =_xlfn.XLOOKUP($A32,BS!$A$1:$A$36,BS!C$1:C$36,,0,1)/_xlfn.XLOOKUP($A$20,BS!$A$1:$A$36,BS!C$1:C$36,,0,1) | D32: =_xlfn.XLOOKUP($A32,BS!$A$1:$A$36,BS!D$1:D$36,,0,1)/_xlfn.XLOOKUP($A$20,BS!$A$1:$A$36,BS!D$1:D$36,,0,1) | E32: =_xlfn.XLOOKUP($A32,BS!$A$1:$A$36,BS!E$1:E$36,,0,1)/_xlfn.XLOOKUP($A$20,BS!$A$1:$A$36,BS!E$1:E$36,,0,1) | F32: =_xlfn.XLOOKUP($A32,BS!$A$1:$A$36,BS!F$1:F$36,,0,1)/_xlfn.XLOOKUP($A$20,BS!$A$1:$A$36,BS!F$1:F$36,,0,1)
